Successfully authenticated!
1602961262508867688533076854428069729894215845456539738681467050391872100995296187545974783861866242834182155532486571078748902416254925870463775142568197
-------------------------------------------------------------------------------------------------
Successfully authenticated!
1602961262508867688533076854428069729894215845456539738681467050391872100995296187545974783861866242834182155532486571078748902416254925870463775142568197
-------------------------------------------------------------------------------------------------
Successfully authenticated!
1602961262508867688533076854428069729894215845456539738681467050391872100995296187545974783861866242834182155532486571078748902416254925870463775142568197
-------------------------------------------------------------------------------------------------
Traceback (most recent call last):
  File "/mnt/c/BioMessages/reed_solomon/authentication.py", line 60, in authentication
    decoded_features = rsc.decode(padded_features)[0]
  File "/home/bread98/.local/lib/python3.8/site-packages/reedsolo.py", line 940, in decode
    rmes, recc, errata_pos = rs_correct_msg(chunk, nsym, fcr=self.fcr, generator=self.generator, erase_pos=e_pos, only_erasures=only_erasures)
  File "/home/bread98/.local/lib/python3.8/site-packages/reedsolo.py", line 748, in rs_correct_msg
    err_loc = rs_find_error_locator(fsynd, nsym, erase_count=len(erase_pos))
  File "/home/bread98/.local/lib/python3.8/site-packages/reedsolo.py", line 659, in rs_find_error_locator
    raise ReedSolomonError("Too many errors to correct")
reedsolo.ReedSolomonError: Too many errors to correct

Wrong user!
-------------------------------------------------------------------------------------------------



Successfully authenticated!
6799576826491945237562475026187636402117358048711989348199016090786650037183465499512254026228407025073576373886336970171917997602164833808982622753732608
-------------------------------------------------------------------------------------------------
Traceback (most recent call last):
  File "/mnt/c/BioMessages/reed_solomon/authentication.py", line 60, in authentication
    decoded_features = rsc.decode(padded_features)[0]
  File "/home/bread98/.local/lib/python3.8/site-packages/reedsolo.py", line 940, in decode
    rmes, recc, errata_pos = rs_correct_msg(chunk, nsym, fcr=self.fcr, generator=self.generator, erase_pos=e_pos, only_erasures=only_erasures)
  File "/home/bread98/.local/lib/python3.8/site-packages/reedsolo.py", line 748, in rs_correct_msg
    err_loc = rs_find_error_locator(fsynd, nsym, erase_count=len(erase_pos))
  File "/home/bread98/.local/lib/python3.8/site-packages/reedsolo.py", line 659, in rs_find_error_locator
    raise ReedSolomonError("Too many errors to correct")
reedsolo.ReedSolomonError: Too many errors to correct

Wrong user!
-------------------------------------------------------------------------------------------------
Traceback (most recent call last):
  File "/mnt/c/BioMessages/reed_solomon/authentication.py", line 60, in authentication
    decoded_features = rsc.decode(padded_features)[0]
  File "/home/bread98/.local/lib/python3.8/site-packages/reedsolo.py", line 940, in decode
    rmes, recc, errata_pos = rs_correct_msg(chunk, nsym, fcr=self.fcr, generator=self.generator, erase_pos=e_pos, only_erasures=only_erasures)
  File "/home/bread98/.local/lib/python3.8/site-packages/reedsolo.py", line 748, in rs_correct_msg
    err_loc = rs_find_error_locator(fsynd, nsym, erase_count=len(erase_pos))
  File "/home/bread98/.local/lib/python3.8/site-packages/reedsolo.py", line 659, in rs_find_error_locator
    raise ReedSolomonError("Too many errors to correct")
reedsolo.ReedSolomonError: Too many errors to correct

Wrong user!
-------------------------------------------------------------------------------------------------
Successfully authenticated!
6799576826491945237562475026187636402117358048711989348199016090786650037183465499512254026228407025073576373886336970171917997602164833808982622753732608
-------------------------------------------------------------------------------------------------



Successfully authenticated!
4919345880170747410124074816938099321046331314675714461093971663168031176835297933685691891983332520176106224885872927479805920810482117665208970876939991
-------------------------------------------------------------------------------------------------
Successfully authenticated!
4919345880170747410124074816938099321046331314675714461093971663168031176835297933685691891983332520176106224885872927479805920810482117665208970876939991
-------------------------------------------------------------------------------------------------
Successfully authenticated!
4919345880170747410124074816938099321046331314675714461093971663168031176835297933685691891983332520176106224885872927479805920810482117665208970876939991
-------------------------------------------------------------------------------------------------
Traceback (most recent call last):
  File "/mnt/c/BioMessages/reed_solomon/authentication.py", line 60, in authentication
    decoded_features = rsc.decode(padded_features)[0]
  File "/home/bread98/.local/lib/python3.8/site-packages/reedsolo.py", line 940, in decode
    rmes, recc, errata_pos = rs_correct_msg(chunk, nsym, fcr=self.fcr, generator=self.generator, erase_pos=e_pos, only_erasures=only_erasures)
  File "/home/bread98/.local/lib/python3.8/site-packages/reedsolo.py", line 748, in rs_correct_msg
    err_loc = rs_find_error_locator(fsynd, nsym, erase_count=len(erase_pos))
  File "/home/bread98/.local/lib/python3.8/site-packages/reedsolo.py", line 659, in rs_find_error_locator
    raise ReedSolomonError("Too many errors to correct")
reedsolo.ReedSolomonError: Too many errors to correct

Wrong user!
-------------------------------------------------------------------------------------------------



Successfully authenticated!
2959776418919085696812572759476968879643152657689194473528314791368805446093232816248182114782894364677426280608239589495247865735585949864249885775237877
-------------------------------------------------------------------------------------------------
Successfully authenticated!
2959776418919085696812572759476968879643152657689194473528314791368805446093232816248182114782894364677426280608239589495247865735585949864249885775237877
-------------------------------------------------------------------------------------------------
Successfully authenticated!
2959776418919085696812572759476968879643152657689194473528314791368805446093232816248182114782894364677426280608239589495247865735585949864249885775237877
-------------------------------------------------------------------------------------------------
Traceback (most recent call last):
  File "/mnt/c/BioMessages/reed_solomon/authentication.py", line 60, in authentication
    decoded_features = rsc.decode(padded_features)[0]
  File "/home/bread98/.local/lib/python3.8/site-packages/reedsolo.py", line 940, in decode
    rmes, recc, errata_pos = rs_correct_msg(chunk, nsym, fcr=self.fcr, generator=self.generator, erase_pos=e_pos, only_erasures=only_erasures)
  File "/home/bread98/.local/lib/python3.8/site-packages/reedsolo.py", line 748, in rs_correct_msg
    err_loc = rs_find_error_locator(fsynd, nsym, erase_count=len(erase_pos))
  File "/home/bread98/.local/lib/python3.8/site-packages/reedsolo.py", line 659, in rs_find_error_locator
    raise ReedSolomonError("Too many errors to correct")
reedsolo.ReedSolomonError: Too many errors to correct

Wrong user!
-------------------------------------------------------------------------------------------------



Successfully authenticated!
9301472798479629321802205290651594601435677057526587459688974373365184322561337245626774568342943281361065717469725368251718842460632168913342697175978980
-------------------------------------------------------------------------------------------------
Successfully authenticated!
9301472798479629321802205290651594601435677057526587459688974373365184322561337245626774568342943281361065717469725368251718842460632168913342697175978980
-------------------------------------------------------------------------------------------------
Traceback (most recent call last):
  File "/mnt/c/BioMessages/reed_solomon/authentication.py", line 60, in authentication
    decoded_features = rsc.decode(padded_features)[0]
  File "/home/bread98/.local/lib/python3.8/site-packages/reedsolo.py", line 940, in decode
    rmes, recc, errata_pos = rs_correct_msg(chunk, nsym, fcr=self.fcr, generator=self.generator, erase_pos=e_pos, only_erasures=only_erasures)
  File "/home/bread98/.local/lib/python3.8/site-packages/reedsolo.py", line 748, in rs_correct_msg
    err_loc = rs_find_error_locator(fsynd, nsym, erase_count=len(erase_pos))
  File "/home/bread98/.local/lib/python3.8/site-packages/reedsolo.py", line 659, in rs_find_error_locator
    raise ReedSolomonError("Too many errors to correct")
reedsolo.ReedSolomonError: Too many errors to correct

Wrong user!
-------------------------------------------------------------------------------------------------
Traceback (most recent call last):
  File "/mnt/c/BioMessages/reed_solomon/authentication.py", line 60, in authentication
    decoded_features = rsc.decode(padded_features)[0]
  File "/home/bread98/.local/lib/python3.8/site-packages/reedsolo.py", line 940, in decode
    rmes, recc, errata_pos = rs_correct_msg(chunk, nsym, fcr=self.fcr, generator=self.generator, erase_pos=e_pos, only_erasures=only_erasures)
  File "/home/bread98/.local/lib/python3.8/site-packages/reedsolo.py", line 748, in rs_correct_msg
    err_loc = rs_find_error_locator(fsynd, nsym, erase_count=len(erase_pos))
  File "/home/bread98/.local/lib/python3.8/site-packages/reedsolo.py", line 659, in rs_find_error_locator
    raise ReedSolomonError("Too many errors to correct")
reedsolo.ReedSolomonError: Too many errors to correct

Wrong user!
-------------------------------------------------------------------------------------------------



Successfully authenticated!
6331054118262148857149858030216778245456368326875265766053959128616293461957239692326833736084072219928849306311899308526530051628912254422268418966737800
-------------------------------------------------------------------------------------------------
Successfully authenticated!
6331054118262148857149858030216778245456368326875265766053959128616293461957239692326833736084072219928849306311899308526530051628912254422268418966737800
-------------------------------------------------------------------------------------------------
Successfully authenticated!
6331054118262148857149858030216778245456368326875265766053959128616293461957239692326833736084072219928849306311899308526530051628912254422268418966737800
-------------------------------------------------------------------------------------------------
Successfully authenticated!
6331054118262148857149858030216778245456368326875265766053959128616293461957239692326833736084072219928849306311899308526530051628912254422268418966737800
-------------------------------------------------------------------------------------------------



Successfully authenticated!
11200492376268279366048948172362287963529463568244760805422770188532956830635100175577070894029170031479642214925704573906037825873128548855300611800048687
-------------------------------------------------------------------------------------------------
Traceback (most recent call last):
  File "/mnt/c/BioMessages/reed_solomon/authentication.py", line 60, in authentication
    decoded_features = rsc.decode(padded_features)[0]
  File "/home/bread98/.local/lib/python3.8/site-packages/reedsolo.py", line 940, in decode
    rmes, recc, errata_pos = rs_correct_msg(chunk, nsym, fcr=self.fcr, generator=self.generator, erase_pos=e_pos, only_erasures=only_erasures)
  File "/home/bread98/.local/lib/python3.8/site-packages/reedsolo.py", line 748, in rs_correct_msg
    err_loc = rs_find_error_locator(fsynd, nsym, erase_count=len(erase_pos))
  File "/home/bread98/.local/lib/python3.8/site-packages/reedsolo.py", line 659, in rs_find_error_locator
    raise ReedSolomonError("Too many errors to correct")
reedsolo.ReedSolomonError: Too many errors to correct

Wrong user!
-------------------------------------------------------------------------------------------------
Traceback (most recent call last):
  File "/mnt/c/BioMessages/reed_solomon/authentication.py", line 60, in authentication
    decoded_features = rsc.decode(padded_features)[0]
  File "/home/bread98/.local/lib/python3.8/site-packages/reedsolo.py", line 940, in decode
    rmes, recc, errata_pos = rs_correct_msg(chunk, nsym, fcr=self.fcr, generator=self.generator, erase_pos=e_pos, only_erasures=only_erasures)
  File "/home/bread98/.local/lib/python3.8/site-packages/reedsolo.py", line 748, in rs_correct_msg
    err_loc = rs_find_error_locator(fsynd, nsym, erase_count=len(erase_pos))
  File "/home/bread98/.local/lib/python3.8/site-packages/reedsolo.py", line 659, in rs_find_error_locator
    raise ReedSolomonError("Too many errors to correct")
reedsolo.ReedSolomonError: Too many errors to correct

Wrong user!
-------------------------------------------------------------------------------------------------
Traceback (most recent call last):
  File "/mnt/c/BioMessages/reed_solomon/authentication.py", line 60, in authentication
    decoded_features = rsc.decode(padded_features)[0]
  File "/home/bread98/.local/lib/python3.8/site-packages/reedsolo.py", line 940, in decode
    rmes, recc, errata_pos = rs_correct_msg(chunk, nsym, fcr=self.fcr, generator=self.generator, erase_pos=e_pos, only_erasures=only_erasures)
  File "/home/bread98/.local/lib/python3.8/site-packages/reedsolo.py", line 748, in rs_correct_msg
    err_loc = rs_find_error_locator(fsynd, nsym, erase_count=len(erase_pos))
  File "/home/bread98/.local/lib/python3.8/site-packages/reedsolo.py", line 659, in rs_find_error_locator
    raise ReedSolomonError("Too many errors to correct")
reedsolo.ReedSolomonError: Too many errors to correct

Wrong user!
-------------------------------------------------------------------------------------------------



Successfully authenticated!
911662448892656842514454210527848227514013854011363591757501423430036918747075056934891615370990130840897196425540962071399576705522753570423249779448645
-------------------------------------------------------------------------------------------------
Traceback (most recent call last):
  File "/mnt/c/BioMessages/reed_solomon/authentication.py", line 60, in authentication
    decoded_features = rsc.decode(padded_features)[0]
  File "/home/bread98/.local/lib/python3.8/site-packages/reedsolo.py", line 940, in decode
    rmes, recc, errata_pos = rs_correct_msg(chunk, nsym, fcr=self.fcr, generator=self.generator, erase_pos=e_pos, only_erasures=only_erasures)
  File "/home/bread98/.local/lib/python3.8/site-packages/reedsolo.py", line 748, in rs_correct_msg
    err_loc = rs_find_error_locator(fsynd, nsym, erase_count=len(erase_pos))
  File "/home/bread98/.local/lib/python3.8/site-packages/reedsolo.py", line 659, in rs_find_error_locator
    raise ReedSolomonError("Too many errors to correct")
reedsolo.ReedSolomonError: Too many errors to correct

Wrong user!
-------------------------------------------------------------------------------------------------
Successfully authenticated!
911662448892656842514454210527848227514013854011363591757501423430036918747075056934891615370990130840897196425540962071399576705522753570423249779448645
-------------------------------------------------------------------------------------------------
Successfully authenticated!
911662448892656842514454210527848227514013854011363591757501423430036918747075056934891615370990130840897196425540962071399576705522753570423249779448645
-------------------------------------------------------------------------------------------------



Successfully authenticated!
13148710221187001327092182381863767569779143508609095769359973592862423934192034052728547063219673776441609161627191436705700358997762290873439402827671813
-------------------------------------------------------------------------------------------------
Traceback (most recent call last):
  File "/mnt/c/BioMessages/reed_solomon/authentication.py", line 60, in authentication
    decoded_features = rsc.decode(padded_features)[0]
  File "/home/bread98/.local/lib/python3.8/site-packages/reedsolo.py", line 940, in decode
    rmes, recc, errata_pos = rs_correct_msg(chunk, nsym, fcr=self.fcr, generator=self.generator, erase_pos=e_pos, only_erasures=only_erasures)
  File "/home/bread98/.local/lib/python3.8/site-packages/reedsolo.py", line 748, in rs_correct_msg
    err_loc = rs_find_error_locator(fsynd, nsym, erase_count=len(erase_pos))
  File "/home/bread98/.local/lib/python3.8/site-packages/reedsolo.py", line 659, in rs_find_error_locator
    raise ReedSolomonError("Too many errors to correct")
reedsolo.ReedSolomonError: Too many errors to correct

Wrong user!
-------------------------------------------------------------------------------------------------
Traceback (most recent call last):
  File "/mnt/c/BioMessages/reed_solomon/authentication.py", line 60, in authentication
    decoded_features = rsc.decode(padded_features)[0]
  File "/home/bread98/.local/lib/python3.8/site-packages/reedsolo.py", line 940, in decode
    rmes, recc, errata_pos = rs_correct_msg(chunk, nsym, fcr=self.fcr, generator=self.generator, erase_pos=e_pos, only_erasures=only_erasures)
  File "/home/bread98/.local/lib/python3.8/site-packages/reedsolo.py", line 748, in rs_correct_msg
    err_loc = rs_find_error_locator(fsynd, nsym, erase_count=len(erase_pos))
  File "/home/bread98/.local/lib/python3.8/site-packages/reedsolo.py", line 659, in rs_find_error_locator
    raise ReedSolomonError("Too many errors to correct")
reedsolo.ReedSolomonError: Too many errors to correct

Wrong user!
-------------------------------------------------------------------------------------------------
Traceback (most recent call last):
  File "/mnt/c/BioMessages/reed_solomon/authentication.py", line 60, in authentication
    decoded_features = rsc.decode(padded_features)[0]
  File "/home/bread98/.local/lib/python3.8/site-packages/reedsolo.py", line 940, in decode
    rmes, recc, errata_pos = rs_correct_msg(chunk, nsym, fcr=self.fcr, generator=self.generator, erase_pos=e_pos, only_erasures=only_erasures)
  File "/home/bread98/.local/lib/python3.8/site-packages/reedsolo.py", line 748, in rs_correct_msg
    err_loc = rs_find_error_locator(fsynd, nsym, erase_count=len(erase_pos))
  File "/home/bread98/.local/lib/python3.8/site-packages/reedsolo.py", line 659, in rs_find_error_locator
    raise ReedSolomonError("Too many errors to correct")
reedsolo.ReedSolomonError: Too many errors to correct

Wrong user!
-------------------------------------------------------------------------------------------------



Successfully authenticated!
2455601763046328380044293368514976426155220855161293939114297482268517318171911491028263147257345272589113457449652209040933833989338435299920432278865857
-------------------------------------------------------------------------------------------------
Successfully authenticated!
2455601763046328380044293368514976426155220855161293939114297482268517318171911491028263147257345272589113457449652209040933833989338435299920432278865857
-------------------------------------------------------------------------------------------------
Successfully authenticated!
2455601763046328380044293368514976426155220855161293939114297482268517318171911491028263147257345272589113457449652209040933833989338435299920432278865857
-------------------------------------------------------------------------------------------------
Successfully authenticated!
2455601763046328380044293368514976426155220855161293939114297482268517318171911491028263147257345272589113457449652209040933833989338435299920432278865857
-------------------------------------------------------------------------------------------------



Successfully authenticated!
11274797292274428335010662493299068260767445902144210904071976724218009847371408767147776232559112140406113682129000230357075900193884804416280543635579535
-------------------------------------------------------------------------------------------------
Successfully authenticated!
11274797292274428335010662493299068260767445902144210904071976724218009847371408767147776232559112140406113682129000230357075900193884804416280543635579535
-------------------------------------------------------------------------------------------------
Traceback (most recent call last):
  File "/mnt/c/BioMessages/reed_solomon/authentication.py", line 60, in authentication
    decoded_features = rsc.decode(padded_features)[0]
  File "/home/bread98/.local/lib/python3.8/site-packages/reedsolo.py", line 940, in decode
    rmes, recc, errata_pos = rs_correct_msg(chunk, nsym, fcr=self.fcr, generator=self.generator, erase_pos=e_pos, only_erasures=only_erasures)
  File "/home/bread98/.local/lib/python3.8/site-packages/reedsolo.py", line 748, in rs_correct_msg
    err_loc = rs_find_error_locator(fsynd, nsym, erase_count=len(erase_pos))
  File "/home/bread98/.local/lib/python3.8/site-packages/reedsolo.py", line 659, in rs_find_error_locator
    raise ReedSolomonError("Too many errors to correct")
reedsolo.ReedSolomonError: Too many errors to correct

Wrong user!
-------------------------------------------------------------------------------------------------
Successfully authenticated!
11274797292274428335010662493299068260767445902144210904071976724218009847371408767147776232559112140406113682129000230357075900193884804416280543635579535
-------------------------------------------------------------------------------------------------



Successfully authenticated!
5294794909183975476745776678336913448889524096223877696980087820946355923506624947416891521366895102131974226373748081022977917206682918737851402926931004
-------------------------------------------------------------------------------------------------
Traceback (most recent call last):
  File "/mnt/c/BioMessages/reed_solomon/authentication.py", line 60, in authentication
    decoded_features = rsc.decode(padded_features)[0]
  File "/home/bread98/.local/lib/python3.8/site-packages/reedsolo.py", line 940, in decode
    rmes, recc, errata_pos = rs_correct_msg(chunk, nsym, fcr=self.fcr, generator=self.generator, erase_pos=e_pos, only_erasures=only_erasures)
  File "/home/bread98/.local/lib/python3.8/site-packages/reedsolo.py", line 748, in rs_correct_msg
    err_loc = rs_find_error_locator(fsynd, nsym, erase_count=len(erase_pos))
  File "/home/bread98/.local/lib/python3.8/site-packages/reedsolo.py", line 659, in rs_find_error_locator
    raise ReedSolomonError("Too many errors to correct")
reedsolo.ReedSolomonError: Too many errors to correct

Wrong user!
-------------------------------------------------------------------------------------------------
Traceback (most recent call last):
  File "/mnt/c/BioMessages/reed_solomon/authentication.py", line 60, in authentication
    decoded_features = rsc.decode(padded_features)[0]
  File "/home/bread98/.local/lib/python3.8/site-packages/reedsolo.py", line 940, in decode
    rmes, recc, errata_pos = rs_correct_msg(chunk, nsym, fcr=self.fcr, generator=self.generator, erase_pos=e_pos, only_erasures=only_erasures)
  File "/home/bread98/.local/lib/python3.8/site-packages/reedsolo.py", line 748, in rs_correct_msg
    err_loc = rs_find_error_locator(fsynd, nsym, erase_count=len(erase_pos))
  File "/home/bread98/.local/lib/python3.8/site-packages/reedsolo.py", line 659, in rs_find_error_locator
    raise ReedSolomonError("Too many errors to correct")
reedsolo.ReedSolomonError: Too many errors to correct

Wrong user!
-------------------------------------------------------------------------------------------------
Traceback (most recent call last):
  File "/mnt/c/BioMessages/reed_solomon/authentication.py", line 60, in authentication
    decoded_features = rsc.decode(padded_features)[0]
  File "/home/bread98/.local/lib/python3.8/site-packages/reedsolo.py", line 940, in decode
    rmes, recc, errata_pos = rs_correct_msg(chunk, nsym, fcr=self.fcr, generator=self.generator, erase_pos=e_pos, only_erasures=only_erasures)
  File "/home/bread98/.local/lib/python3.8/site-packages/reedsolo.py", line 748, in rs_correct_msg
    err_loc = rs_find_error_locator(fsynd, nsym, erase_count=len(erase_pos))
  File "/home/bread98/.local/lib/python3.8/site-packages/reedsolo.py", line 659, in rs_find_error_locator
    raise ReedSolomonError("Too many errors to correct")
reedsolo.ReedSolomonError: Too many errors to correct

Wrong user!
-------------------------------------------------------------------------------------------------



Successfully authenticated!
2016899488292343064397881993031774110048805307194544165757073096492587335358252722980662806049918761439408637233543400852234960400187164321223360140311261
-------------------------------------------------------------------------------------------------
Successfully authenticated!
2016899488292343064397881993031774110048805307194544165757073096492587335358252722980662806049918761439408637233543400852234960400187164321223360140311261
-------------------------------------------------------------------------------------------------
Successfully authenticated!
2016899488292343064397881993031774110048805307194544165757073096492587335358252722980662806049918761439408637233543400852234960400187164321223360140311261
-------------------------------------------------------------------------------------------------
Successfully authenticated!
2016899488292343064397881993031774110048805307194544165757073096492587335358252722980662806049918761439408637233543400852234960400187164321223360140311261
-------------------------------------------------------------------------------------------------



Successfully authenticated!
8695990434009727528535745856299969613649767978837180824878433597574274702274386327187553600130667151392815063304377863125894015726754626884482701262080164
-------------------------------------------------------------------------------------------------
Successfully authenticated!
8695990434009727528535745856299969613649767978837180824878433597574274702274386327187553600130667151392815063304377863125894015726754626884482701262080164
-------------------------------------------------------------------------------------------------
Successfully authenticated!
8695990434009727528535745856299969613649767978837180824878433597574274702274386327187553600130667151392815063304377863125894015726754626884482701262080164
-------------------------------------------------------------------------------------------------
Traceback (most recent call last):
  File "/mnt/c/BioMessages/reed_solomon/authentication.py", line 60, in authentication
    decoded_features = rsc.decode(padded_features)[0]
  File "/home/bread98/.local/lib/python3.8/site-packages/reedsolo.py", line 940, in decode
    rmes, recc, errata_pos = rs_correct_msg(chunk, nsym, fcr=self.fcr, generator=self.generator, erase_pos=e_pos, only_erasures=only_erasures)
  File "/home/bread98/.local/lib/python3.8/site-packages/reedsolo.py", line 748, in rs_correct_msg
    err_loc = rs_find_error_locator(fsynd, nsym, erase_count=len(erase_pos))
  File "/home/bread98/.local/lib/python3.8/site-packages/reedsolo.py", line 659, in rs_find_error_locator
    raise ReedSolomonError("Too many errors to correct")
reedsolo.ReedSolomonError: Too many errors to correct

Wrong user!
-------------------------------------------------------------------------------------------------



Successfully authenticated!
10012081728707138659755952358388872044855526776883355209525343900932393981365700685601168527997038397146570920974358522008428763738511602312534610009275326
-------------------------------------------------------------------------------------------------
Successfully authenticated!
10012081728707138659755952358388872044855526776883355209525343900932393981365700685601168527997038397146570920974358522008428763738511602312534610009275326
-------------------------------------------------------------------------------------------------
Traceback (most recent call last):
  File "/mnt/c/BioMessages/reed_solomon/authentication.py", line 60, in authentication
    decoded_features = rsc.decode(padded_features)[0]
  File "/home/bread98/.local/lib/python3.8/site-packages/reedsolo.py", line 940, in decode
    rmes, recc, errata_pos = rs_correct_msg(chunk, nsym, fcr=self.fcr, generator=self.generator, erase_pos=e_pos, only_erasures=only_erasures)
  File "/home/bread98/.local/lib/python3.8/site-packages/reedsolo.py", line 748, in rs_correct_msg
    err_loc = rs_find_error_locator(fsynd, nsym, erase_count=len(erase_pos))
  File "/home/bread98/.local/lib/python3.8/site-packages/reedsolo.py", line 659, in rs_find_error_locator
    raise ReedSolomonError("Too many errors to correct")
reedsolo.ReedSolomonError: Too many errors to correct

Wrong user!
-------------------------------------------------------------------------------------------------
Traceback (most recent call last):
  File "/mnt/c/BioMessages/reed_solomon/authentication.py", line 60, in authentication
    decoded_features = rsc.decode(padded_features)[0]
  File "/home/bread98/.local/lib/python3.8/site-packages/reedsolo.py", line 940, in decode
    rmes, recc, errata_pos = rs_correct_msg(chunk, nsym, fcr=self.fcr, generator=self.generator, erase_pos=e_pos, only_erasures=only_erasures)
  File "/home/bread98/.local/lib/python3.8/site-packages/reedsolo.py", line 748, in rs_correct_msg
    err_loc = rs_find_error_locator(fsynd, nsym, erase_count=len(erase_pos))
  File "/home/bread98/.local/lib/python3.8/site-packages/reedsolo.py", line 659, in rs_find_error_locator
    raise ReedSolomonError("Too many errors to correct")
reedsolo.ReedSolomonError: Too many errors to correct

Wrong user!
-------------------------------------------------------------------------------------------------



Successfully authenticated!
7554461811320399696340356743241316825580876751782629341648109545740965679427349841262156313911666458713099158839352418299242533969146584407571627389761940
-------------------------------------------------------------------------------------------------
Successfully authenticated!
7554461811320399696340356743241316825580876751782629341648109545740965679427349841262156313911666458713099158839352418299242533969146584407571627389761940
-------------------------------------------------------------------------------------------------
Successfully authenticated!
7554461811320399696340356743241316825580876751782629341648109545740965679427349841262156313911666458713099158839352418299242533969146584407571627389761940
-------------------------------------------------------------------------------------------------
Traceback (most recent call last):
  File "/mnt/c/BioMessages/reed_solomon/authentication.py", line 60, in authentication
    decoded_features = rsc.decode(padded_features)[0]
  File "/home/bread98/.local/lib/python3.8/site-packages/reedsolo.py", line 940, in decode
    rmes, recc, errata_pos = rs_correct_msg(chunk, nsym, fcr=self.fcr, generator=self.generator, erase_pos=e_pos, only_erasures=only_erasures)
  File "/home/bread98/.local/lib/python3.8/site-packages/reedsolo.py", line 748, in rs_correct_msg
    err_loc = rs_find_error_locator(fsynd, nsym, erase_count=len(erase_pos))
  File "/home/bread98/.local/lib/python3.8/site-packages/reedsolo.py", line 659, in rs_find_error_locator
    raise ReedSolomonError("Too many errors to correct")
reedsolo.ReedSolomonError: Too many errors to correct

Wrong user!
-------------------------------------------------------------------------------------------------



Successfully authenticated!
8693819290036870459640401686338816360779646781091671122037785882611914588785906848210415917191476969032638303331416808477645285111720952322569223189907685
-------------------------------------------------------------------------------------------------
Successfully authenticated!
8693819290036870459640401686338816360779646781091671122037785882611914588785906848210415917191476969032638303331416808477645285111720952322569223189907685
-------------------------------------------------------------------------------------------------
Successfully authenticated!
8693819290036870459640401686338816360779646781091671122037785882611914588785906848210415917191476969032638303331416808477645285111720952322569223189907685
-------------------------------------------------------------------------------------------------
Successfully authenticated!
8693819290036870459640401686338816360779646781091671122037785882611914588785906848210415917191476969032638303331416808477645285111720952322569223189907685
-------------------------------------------------------------------------------------------------



Successfully authenticated!
5250494003087471443096664843501731197707426279501170991835004489533701087107846563471311674154423039840351531222829461911440934676925492418223194712595383
-------------------------------------------------------------------------------------------------
Traceback (most recent call last):
  File "/mnt/c/BioMessages/reed_solomon/authentication.py", line 60, in authentication
    decoded_features = rsc.decode(padded_features)[0]
  File "/home/bread98/.local/lib/python3.8/site-packages/reedsolo.py", line 940, in decode
    rmes, recc, errata_pos = rs_correct_msg(chunk, nsym, fcr=self.fcr, generator=self.generator, erase_pos=e_pos, only_erasures=only_erasures)
  File "/home/bread98/.local/lib/python3.8/site-packages/reedsolo.py", line 748, in rs_correct_msg
    err_loc = rs_find_error_locator(fsynd, nsym, erase_count=len(erase_pos))
  File "/home/bread98/.local/lib/python3.8/site-packages/reedsolo.py", line 659, in rs_find_error_locator
    raise ReedSolomonError("Too many errors to correct")
reedsolo.ReedSolomonError: Too many errors to correct

Wrong user!
-------------------------------------------------------------------------------------------------
Traceback (most recent call last):
  File "/mnt/c/BioMessages/reed_solomon/authentication.py", line 60, in authentication
    decoded_features = rsc.decode(padded_features)[0]
  File "/home/bread98/.local/lib/python3.8/site-packages/reedsolo.py", line 940, in decode
    rmes, recc, errata_pos = rs_correct_msg(chunk, nsym, fcr=self.fcr, generator=self.generator, erase_pos=e_pos, only_erasures=only_erasures)
  File "/home/bread98/.local/lib/python3.8/site-packages/reedsolo.py", line 748, in rs_correct_msg
    err_loc = rs_find_error_locator(fsynd, nsym, erase_count=len(erase_pos))
  File "/home/bread98/.local/lib/python3.8/site-packages/reedsolo.py", line 659, in rs_find_error_locator
    raise ReedSolomonError("Too many errors to correct")
reedsolo.ReedSolomonError: Too many errors to correct

Wrong user!
-------------------------------------------------------------------------------------------------
Traceback (most recent call last):
  File "/mnt/c/BioMessages/reed_solomon/authentication.py", line 60, in authentication
    decoded_features = rsc.decode(padded_features)[0]
  File "/home/bread98/.local/lib/python3.8/site-packages/reedsolo.py", line 940, in decode
    rmes, recc, errata_pos = rs_correct_msg(chunk, nsym, fcr=self.fcr, generator=self.generator, erase_pos=e_pos, only_erasures=only_erasures)
  File "/home/bread98/.local/lib/python3.8/site-packages/reedsolo.py", line 748, in rs_correct_msg
    err_loc = rs_find_error_locator(fsynd, nsym, erase_count=len(erase_pos))
  File "/home/bread98/.local/lib/python3.8/site-packages/reedsolo.py", line 659, in rs_find_error_locator
    raise ReedSolomonError("Too many errors to correct")
reedsolo.ReedSolomonError: Too many errors to correct

Wrong user!
-------------------------------------------------------------------------------------------------



Successfully authenticated!
10559928779648426354903562417748913804560499147589671128408559532104646283695271316595984715900492802386011879763127856244296764012693758428806824993800478
-------------------------------------------------------------------------------------------------
Successfully authenticated!
10559928779648426354903562417748913804560499147589671128408559532104646283695271316595984715900492802386011879763127856244296764012693758428806824993800478
-------------------------------------------------------------------------------------------------
Successfully authenticated!
10559928779648426354903562417748913804560499147589671128408559532104646283695271316595984715900492802386011879763127856244296764012693758428806824993800478
-------------------------------------------------------------------------------------------------
Successfully authenticated!
10559928779648426354903562417748913804560499147589671128408559532104646283695271316595984715900492802386011879763127856244296764012693758428806824993800478
-------------------------------------------------------------------------------------------------



Successfully authenticated!
2062144011410720958622345608382998041225407158023646103161203927628647103964689265684734960980833458877564583324484962152655447378489037705850838139060776
-------------------------------------------------------------------------------------------------
Successfully authenticated!
2062144011410720958622345608382998041225407158023646103161203927628647103964689265684734960980833458877564583324484962152655447378489037705850838139060776
-------------------------------------------------------------------------------------------------
Successfully authenticated!
2062144011410720958622345608382998041225407158023646103161203927628647103964689265684734960980833458877564583324484962152655447378489037705850838139060776
-------------------------------------------------------------------------------------------------
Successfully authenticated!
2062144011410720958622345608382998041225407158023646103161203927628647103964689265684734960980833458877564583324484962152655447378489037705850838139060776
-------------------------------------------------------------------------------------------------



Successfully authenticated!
8048648444425760483640518975442239587425114109960388871784107398283627543891609695578646249956819936077999960299451959703394483836038776325535266793425695
-------------------------------------------------------------------------------------------------
Successfully authenticated!
8048648444425760483640518975442239587425114109960388871784107398283627543891609695578646249956819936077999960299451959703394483836038776325535266793425695
-------------------------------------------------------------------------------------------------
Successfully authenticated!
8048648444425760483640518975442239587425114109960388871784107398283627543891609695578646249956819936077999960299451959703394483836038776325535266793425695
-------------------------------------------------------------------------------------------------
Successfully authenticated!
8048648444425760483640518975442239587425114109960388871784107398283627543891609695578646249956819936077999960299451959703394483836038776325535266793425695
-------------------------------------------------------------------------------------------------



Successfully authenticated!
1042028971393534791901755780701682304105295973994914502176900998276650903666220472509105594649435956017462564385470608459247608933975945242128502295712012
-------------------------------------------------------------------------------------------------
Successfully authenticated!
1042028971393534791901755780701682304105295973994914502176900998276650903666220472509105594649435956017462564385470608459247608933975945242128502295712012
-------------------------------------------------------------------------------------------------
Successfully authenticated!
1042028971393534791901755780701682304105295973994914502176900998276650903666220472509105594649435956017462564385470608459247608933975945242128502295712012
-------------------------------------------------------------------------------------------------
Traceback (most recent call last):
  File "/mnt/c/BioMessages/reed_solomon/authentication.py", line 60, in authentication
    decoded_features = rsc.decode(padded_features)[0]
  File "/home/bread98/.local/lib/python3.8/site-packages/reedsolo.py", line 940, in decode
    rmes, recc, errata_pos = rs_correct_msg(chunk, nsym, fcr=self.fcr, generator=self.generator, erase_pos=e_pos, only_erasures=only_erasures)
  File "/home/bread98/.local/lib/python3.8/site-packages/reedsolo.py", line 748, in rs_correct_msg
    err_loc = rs_find_error_locator(fsynd, nsym, erase_count=len(erase_pos))
  File "/home/bread98/.local/lib/python3.8/site-packages/reedsolo.py", line 659, in rs_find_error_locator
    raise ReedSolomonError("Too many errors to correct")
reedsolo.ReedSolomonError: Too many errors to correct

Wrong user!
-------------------------------------------------------------------------------------------------



Successfully authenticated!
3601435455247182822391136329349865397615758376060558828506685670623419972467183396527704684940121542937132839999522320165969118150684997062394109860878641
-------------------------------------------------------------------------------------------------
Traceback (most recent call last):
  File "/mnt/c/BioMessages/reed_solomon/authentication.py", line 60, in authentication
    decoded_features = rsc.decode(padded_features)[0]
  File "/home/bread98/.local/lib/python3.8/site-packages/reedsolo.py", line 940, in decode
    rmes, recc, errata_pos = rs_correct_msg(chunk, nsym, fcr=self.fcr, generator=self.generator, erase_pos=e_pos, only_erasures=only_erasures)
  File "/home/bread98/.local/lib/python3.8/site-packages/reedsolo.py", line 748, in rs_correct_msg
    err_loc = rs_find_error_locator(fsynd, nsym, erase_count=len(erase_pos))
  File "/home/bread98/.local/lib/python3.8/site-packages/reedsolo.py", line 659, in rs_find_error_locator
    raise ReedSolomonError("Too many errors to correct")
reedsolo.ReedSolomonError: Too many errors to correct

Wrong user!
-------------------------------------------------------------------------------------------------
Successfully authenticated!
3601435455247182822391136329349865397615758376060558828506685670623419972467183396527704684940121542937132839999522320165969118150684997062394109860878641
-------------------------------------------------------------------------------------------------
Successfully authenticated!
3601435455247182822391136329349865397615758376060558828506685670623419972467183396527704684940121542937132839999522320165969118150684997062394109860878641
-------------------------------------------------------------------------------------------------



Successfully authenticated!
209668990041396482090697236463067859435186164441244605133899976249753845817513235329087743706770752293319411622108071919829981073850078342223357756204266
-------------------------------------------------------------------------------------------------
Traceback (most recent call last):
  File "/mnt/c/BioMessages/reed_solomon/authentication.py", line 60, in authentication
    decoded_features = rsc.decode(padded_features)[0]
  File "/home/bread98/.local/lib/python3.8/site-packages/reedsolo.py", line 940, in decode
    rmes, recc, errata_pos = rs_correct_msg(chunk, nsym, fcr=self.fcr, generator=self.generator, erase_pos=e_pos, only_erasures=only_erasures)
  File "/home/bread98/.local/lib/python3.8/site-packages/reedsolo.py", line 748, in rs_correct_msg
    err_loc = rs_find_error_locator(fsynd, nsym, erase_count=len(erase_pos))
  File "/home/bread98/.local/lib/python3.8/site-packages/reedsolo.py", line 659, in rs_find_error_locator
    raise ReedSolomonError("Too many errors to correct")
reedsolo.ReedSolomonError: Too many errors to correct

Wrong user!
-------------------------------------------------------------------------------------------------
Traceback (most recent call last):
  File "/mnt/c/BioMessages/reed_solomon/authentication.py", line 60, in authentication
    decoded_features = rsc.decode(padded_features)[0]
  File "/home/bread98/.local/lib/python3.8/site-packages/reedsolo.py", line 940, in decode
    rmes, recc, errata_pos = rs_correct_msg(chunk, nsym, fcr=self.fcr, generator=self.generator, erase_pos=e_pos, only_erasures=only_erasures)
  File "/home/bread98/.local/lib/python3.8/site-packages/reedsolo.py", line 748, in rs_correct_msg
    err_loc = rs_find_error_locator(fsynd, nsym, erase_count=len(erase_pos))
  File "/home/bread98/.local/lib/python3.8/site-packages/reedsolo.py", line 659, in rs_find_error_locator
    raise ReedSolomonError("Too many errors to correct")
reedsolo.ReedSolomonError: Too many errors to correct

Wrong user!
-------------------------------------------------------------------------------------------------
Traceback (most recent call last):
  File "/mnt/c/BioMessages/reed_solomon/authentication.py", line 60, in authentication
    decoded_features = rsc.decode(padded_features)[0]
  File "/home/bread98/.local/lib/python3.8/site-packages/reedsolo.py", line 940, in decode
    rmes, recc, errata_pos = rs_correct_msg(chunk, nsym, fcr=self.fcr, generator=self.generator, erase_pos=e_pos, only_erasures=only_erasures)
  File "/home/bread98/.local/lib/python3.8/site-packages/reedsolo.py", line 748, in rs_correct_msg
    err_loc = rs_find_error_locator(fsynd, nsym, erase_count=len(erase_pos))
  File "/home/bread98/.local/lib/python3.8/site-packages/reedsolo.py", line 659, in rs_find_error_locator
    raise ReedSolomonError("Too many errors to correct")
reedsolo.ReedSolomonError: Too many errors to correct

Wrong user!
-------------------------------------------------------------------------------------------------



Successfully authenticated!
8922404033265703253666330327592549375295461416822196541857057419579865281293753718506717382886589335071581311106651598029640590012313039762855126548820639
-------------------------------------------------------------------------------------------------
Successfully authenticated!
8922404033265703253666330327592549375295461416822196541857057419579865281293753718506717382886589335071581311106651598029640590012313039762855126548820639
-------------------------------------------------------------------------------------------------
Successfully authenticated!
8922404033265703253666330327592549375295461416822196541857057419579865281293753718506717382886589335071581311106651598029640590012313039762855126548820639
-------------------------------------------------------------------------------------------------
Successfully authenticated!
8922404033265703253666330327592549375295461416822196541857057419579865281293753718506717382886589335071581311106651598029640590012313039762855126548820639
-------------------------------------------------------------------------------------------------



Successfully authenticated!
7157922282869342529862247083212380225362240818562625375982862416272757070216305281645913418729316516503844757573137956651797090832051650643659060452947692
-------------------------------------------------------------------------------------------------
Successfully authenticated!
7157922282869342529862247083212380225362240818562625375982862416272757070216305281645913418729316516503844757573137956651797090832051650643659060452947692
-------------------------------------------------------------------------------------------------
Traceback (most recent call last):
  File "/mnt/c/BioMessages/reed_solomon/authentication.py", line 60, in authentication
    decoded_features = rsc.decode(padded_features)[0]
  File "/home/bread98/.local/lib/python3.8/site-packages/reedsolo.py", line 940, in decode
    rmes, recc, errata_pos = rs_correct_msg(chunk, nsym, fcr=self.fcr, generator=self.generator, erase_pos=e_pos, only_erasures=only_erasures)
  File "/home/bread98/.local/lib/python3.8/site-packages/reedsolo.py", line 748, in rs_correct_msg
    err_loc = rs_find_error_locator(fsynd, nsym, erase_count=len(erase_pos))
  File "/home/bread98/.local/lib/python3.8/site-packages/reedsolo.py", line 659, in rs_find_error_locator
    raise ReedSolomonError("Too many errors to correct")
reedsolo.ReedSolomonError: Too many errors to correct

Wrong user!
-------------------------------------------------------------------------------------------------
Successfully authenticated!
7157922282869342529862247083212380225362240818562625375982862416272757070216305281645913418729316516503844757573137956651797090832051650643659060452947692
-------------------------------------------------------------------------------------------------



Successfully authenticated!
11405149329870461121770817796839215315226089657882830247511738040589322649013424775771221693676939234825106103355487404090649878097498206732163003404520647
-------------------------------------------------------------------------------------------------
Successfully authenticated!
11405149329870461121770817796839215315226089657882830247511738040589322649013424775771221693676939234825106103355487404090649878097498206732163003404520647
-------------------------------------------------------------------------------------------------
Successfully authenticated!
11405149329870461121770817796839215315226089657882830247511738040589322649013424775771221693676939234825106103355487404090649878097498206732163003404520647
-------------------------------------------------------------------------------------------------
Successfully authenticated!
11405149329870461121770817796839215315226089657882830247511738040589322649013424775771221693676939234825106103355487404090649878097498206732163003404520647
-------------------------------------------------------------------------------------------------



Successfully authenticated!
1097219665501905828403333209266816233269851632822113372699142383317329925683605624280810239045149775283897163196308319194370310859957943310609120710479685
-------------------------------------------------------------------------------------------------
Successfully authenticated!
1097219665501905828403333209266816233269851632822113372699142383317329925683605624280810239045149775283897163196308319194370310859957943310609120710479685
-------------------------------------------------------------------------------------------------
Successfully authenticated!
1097219665501905828403333209266816233269851632822113372699142383317329925683605624280810239045149775283897163196308319194370310859957943310609120710479685
-------------------------------------------------------------------------------------------------
Traceback (most recent call last):
  File "/mnt/c/BioMessages/reed_solomon/authentication.py", line 60, in authentication
    decoded_features = rsc.decode(padded_features)[0]
  File "/home/bread98/.local/lib/python3.8/site-packages/reedsolo.py", line 940, in decode
    rmes, recc, errata_pos = rs_correct_msg(chunk, nsym, fcr=self.fcr, generator=self.generator, erase_pos=e_pos, only_erasures=only_erasures)
  File "/home/bread98/.local/lib/python3.8/site-packages/reedsolo.py", line 748, in rs_correct_msg
    err_loc = rs_find_error_locator(fsynd, nsym, erase_count=len(erase_pos))
  File "/home/bread98/.local/lib/python3.8/site-packages/reedsolo.py", line 659, in rs_find_error_locator
    raise ReedSolomonError("Too many errors to correct")
reedsolo.ReedSolomonError: Too many errors to correct

Wrong user!
-------------------------------------------------------------------------------------------------



Successfully authenticated!
3144081655796905185794202813456283692260829778717306546726238998697228811915468162834477088539791499720095389265829246676224153499466580873539500332316599
-------------------------------------------------------------------------------------------------
Successfully authenticated!
3144081655796905185794202813456283692260829778717306546726238998697228811915468162834477088539791499720095389265829246676224153499466580873539500332316599
-------------------------------------------------------------------------------------------------
Traceback (most recent call last):
  File "/mnt/c/BioMessages/reed_solomon/authentication.py", line 60, in authentication
    decoded_features = rsc.decode(padded_features)[0]
  File "/home/bread98/.local/lib/python3.8/site-packages/reedsolo.py", line 940, in decode
    rmes, recc, errata_pos = rs_correct_msg(chunk, nsym, fcr=self.fcr, generator=self.generator, erase_pos=e_pos, only_erasures=only_erasures)
  File "/home/bread98/.local/lib/python3.8/site-packages/reedsolo.py", line 748, in rs_correct_msg
    err_loc = rs_find_error_locator(fsynd, nsym, erase_count=len(erase_pos))
  File "/home/bread98/.local/lib/python3.8/site-packages/reedsolo.py", line 659, in rs_find_error_locator
    raise ReedSolomonError("Too many errors to correct")
reedsolo.ReedSolomonError: Too many errors to correct

Wrong user!
-------------------------------------------------------------------------------------------------
Successfully authenticated!
3144081655796905185794202813456283692260829778717306546726238998697228811915468162834477088539791499720095389265829246676224153499466580873539500332316599
-------------------------------------------------------------------------------------------------



Successfully authenticated!
5499409548204669128296693615551676040590623196634567648776927095008906938890947889595085527973030490828039460079911959484908200859077483873796829826415147
-------------------------------------------------------------------------------------------------
Traceback (most recent call last):
  File "/mnt/c/BioMessages/reed_solomon/authentication.py", line 60, in authentication
    decoded_features = rsc.decode(padded_features)[0]
  File "/home/bread98/.local/lib/python3.8/site-packages/reedsolo.py", line 940, in decode
    rmes, recc, errata_pos = rs_correct_msg(chunk, nsym, fcr=self.fcr, generator=self.generator, erase_pos=e_pos, only_erasures=only_erasures)
  File "/home/bread98/.local/lib/python3.8/site-packages/reedsolo.py", line 748, in rs_correct_msg
    err_loc = rs_find_error_locator(fsynd, nsym, erase_count=len(erase_pos))
  File "/home/bread98/.local/lib/python3.8/site-packages/reedsolo.py", line 659, in rs_find_error_locator
    raise ReedSolomonError("Too many errors to correct")
reedsolo.ReedSolomonError: Too many errors to correct

Wrong user!
-------------------------------------------------------------------------------------------------
Successfully authenticated!
5499409548204669128296693615551676040590623196634567648776927095008906938890947889595085527973030490828039460079911959484908200859077483873796829826415147
-------------------------------------------------------------------------------------------------
Successfully authenticated!
5499409548204669128296693615551676040590623196634567648776927095008906938890947889595085527973030490828039460079911959484908200859077483873796829826415147
-------------------------------------------------------------------------------------------------



Successfully authenticated!
8528092925174611381837465532974160770718328579042875650966309101103074977674875503714782030274661379951375756653106444260153306051617922301837941906027330
-------------------------------------------------------------------------------------------------
Traceback (most recent call last):
  File "/mnt/c/BioMessages/reed_solomon/authentication.py", line 60, in authentication
    decoded_features = rsc.decode(padded_features)[0]
  File "/home/bread98/.local/lib/python3.8/site-packages/reedsolo.py", line 940, in decode
    rmes, recc, errata_pos = rs_correct_msg(chunk, nsym, fcr=self.fcr, generator=self.generator, erase_pos=e_pos, only_erasures=only_erasures)
  File "/home/bread98/.local/lib/python3.8/site-packages/reedsolo.py", line 748, in rs_correct_msg
    err_loc = rs_find_error_locator(fsynd, nsym, erase_count=len(erase_pos))
  File "/home/bread98/.local/lib/python3.8/site-packages/reedsolo.py", line 659, in rs_find_error_locator
    raise ReedSolomonError("Too many errors to correct")
reedsolo.ReedSolomonError: Too many errors to correct

Wrong user!
-------------------------------------------------------------------------------------------------
Traceback (most recent call last):
  File "/mnt/c/BioMessages/reed_solomon/authentication.py", line 60, in authentication
    decoded_features = rsc.decode(padded_features)[0]
  File "/home/bread98/.local/lib/python3.8/site-packages/reedsolo.py", line 940, in decode
    rmes, recc, errata_pos = rs_correct_msg(chunk, nsym, fcr=self.fcr, generator=self.generator, erase_pos=e_pos, only_erasures=only_erasures)
  File "/home/bread98/.local/lib/python3.8/site-packages/reedsolo.py", line 748, in rs_correct_msg
    err_loc = rs_find_error_locator(fsynd, nsym, erase_count=len(erase_pos))
  File "/home/bread98/.local/lib/python3.8/site-packages/reedsolo.py", line 659, in rs_find_error_locator
    raise ReedSolomonError("Too many errors to correct")
reedsolo.ReedSolomonError: Too many errors to correct

Wrong user!
-------------------------------------------------------------------------------------------------
Traceback (most recent call last):
  File "/mnt/c/BioMessages/reed_solomon/authentication.py", line 60, in authentication
    decoded_features = rsc.decode(padded_features)[0]
  File "/home/bread98/.local/lib/python3.8/site-packages/reedsolo.py", line 940, in decode
    rmes, recc, errata_pos = rs_correct_msg(chunk, nsym, fcr=self.fcr, generator=self.generator, erase_pos=e_pos, only_erasures=only_erasures)
  File "/home/bread98/.local/lib/python3.8/site-packages/reedsolo.py", line 748, in rs_correct_msg
    err_loc = rs_find_error_locator(fsynd, nsym, erase_count=len(erase_pos))
  File "/home/bread98/.local/lib/python3.8/site-packages/reedsolo.py", line 659, in rs_find_error_locator
    raise ReedSolomonError("Too many errors to correct")
reedsolo.ReedSolomonError: Too many errors to correct

Wrong user!
-------------------------------------------------------------------------------------------------



Successfully authenticated!
6133706385669717337945645609556421811911009123214507928841668675224398188781993426636078605761451706405390985566857719578544146378104457379085885855144023
-------------------------------------------------------------------------------------------------
Successfully authenticated!
6133706385669717337945645609556421811911009123214507928841668675224398188781993426636078605761451706405390985566857719578544146378104457379085885855144023
-------------------------------------------------------------------------------------------------
Successfully authenticated!
6133706385669717337945645609556421811911009123214507928841668675224398188781993426636078605761451706405390985566857719578544146378104457379085885855144023
-------------------------------------------------------------------------------------------------
Successfully authenticated!
6133706385669717337945645609556421811911009123214507928841668675224398188781993426636078605761451706405390985566857719578544146378104457379085885855144023
-------------------------------------------------------------------------------------------------



Successfully authenticated!
946060411532808457448673238623354536978982175207287307798023887848557934751761335068319090594601817063227729725959776282519717528169901692281952521047851
-------------------------------------------------------------------------------------------------
Successfully authenticated!
946060411532808457448673238623354536978982175207287307798023887848557934751761335068319090594601817063227729725959776282519717528169901692281952521047851
-------------------------------------------------------------------------------------------------
Successfully authenticated!
946060411532808457448673238623354536978982175207287307798023887848557934751761335068319090594601817063227729725959776282519717528169901692281952521047851
-------------------------------------------------------------------------------------------------
Successfully authenticated!
946060411532808457448673238623354536978982175207287307798023887848557934751761335068319090594601817063227729725959776282519717528169901692281952521047851
-------------------------------------------------------------------------------------------------



Successfully authenticated!
10926241666053846968618092477969583196213001571692261415506829779613256030945095455418524443709730200632550025027747649567785823701961272199257556116281683
-------------------------------------------------------------------------------------------------
Successfully authenticated!
10926241666053846968618092477969583196213001571692261415506829779613256030945095455418524443709730200632550025027747649567785823701961272199257556116281683
-------------------------------------------------------------------------------------------------
Traceback (most recent call last):
  File "/mnt/c/BioMessages/reed_solomon/authentication.py", line 60, in authentication
    decoded_features = rsc.decode(padded_features)[0]
  File "/home/bread98/.local/lib/python3.8/site-packages/reedsolo.py", line 940, in decode
    rmes, recc, errata_pos = rs_correct_msg(chunk, nsym, fcr=self.fcr, generator=self.generator, erase_pos=e_pos, only_erasures=only_erasures)
  File "/home/bread98/.local/lib/python3.8/site-packages/reedsolo.py", line 748, in rs_correct_msg
    err_loc = rs_find_error_locator(fsynd, nsym, erase_count=len(erase_pos))
  File "/home/bread98/.local/lib/python3.8/site-packages/reedsolo.py", line 659, in rs_find_error_locator
    raise ReedSolomonError("Too many errors to correct")
reedsolo.ReedSolomonError: Too many errors to correct

Wrong user!
-------------------------------------------------------------------------------------------------
Successfully authenticated!
10926241666053846968618092477969583196213001571692261415506829779613256030945095455418524443709730200632550025027747649567785823701961272199257556116281683
-------------------------------------------------------------------------------------------------



Successfully authenticated!
11940379907216026973836290288457831261261952322912903190831040960657486081306228896132958501566404378855729543342645693450257933096870090177062332252045049
-------------------------------------------------------------------------------------------------
Successfully authenticated!
11940379907216026973836290288457831261261952322912903190831040960657486081306228896132958501566404378855729543342645693450257933096870090177062332252045049
-------------------------------------------------------------------------------------------------
Traceback (most recent call last):
  File "/mnt/c/BioMessages/reed_solomon/authentication.py", line 60, in authentication
    decoded_features = rsc.decode(padded_features)[0]
  File "/home/bread98/.local/lib/python3.8/site-packages/reedsolo.py", line 940, in decode
    rmes, recc, errata_pos = rs_correct_msg(chunk, nsym, fcr=self.fcr, generator=self.generator, erase_pos=e_pos, only_erasures=only_erasures)
  File "/home/bread98/.local/lib/python3.8/site-packages/reedsolo.py", line 748, in rs_correct_msg
    err_loc = rs_find_error_locator(fsynd, nsym, erase_count=len(erase_pos))
  File "/home/bread98/.local/lib/python3.8/site-packages/reedsolo.py", line 659, in rs_find_error_locator
    raise ReedSolomonError("Too many errors to correct")
reedsolo.ReedSolomonError: Too many errors to correct

Wrong user!
-------------------------------------------------------------------------------------------------
Traceback (most recent call last):
  File "/mnt/c/BioMessages/reed_solomon/authentication.py", line 60, in authentication
    decoded_features = rsc.decode(padded_features)[0]
  File "/home/bread98/.local/lib/python3.8/site-packages/reedsolo.py", line 940, in decode
    rmes, recc, errata_pos = rs_correct_msg(chunk, nsym, fcr=self.fcr, generator=self.generator, erase_pos=e_pos, only_erasures=only_erasures)
  File "/home/bread98/.local/lib/python3.8/site-packages/reedsolo.py", line 748, in rs_correct_msg
    err_loc = rs_find_error_locator(fsynd, nsym, erase_count=len(erase_pos))
  File "/home/bread98/.local/lib/python3.8/site-packages/reedsolo.py", line 659, in rs_find_error_locator
    raise ReedSolomonError("Too many errors to correct")
reedsolo.ReedSolomonError: Too many errors to correct

Wrong user!
-------------------------------------------------------------------------------------------------



Successfully authenticated!
8433616648366412438958958887441559189241222808507297180123304011037389908596951404223869173957125333028894189288458740593422692852440110628194254331790968
-------------------------------------------------------------------------------------------------
Successfully authenticated!
8433616648366412438958958887441559189241222808507297180123304011037389908596951404223869173957125333028894189288458740593422692852440110628194254331790968
-------------------------------------------------------------------------------------------------
Traceback (most recent call last):
  File "/mnt/c/BioMessages/reed_solomon/authentication.py", line 60, in authentication
    decoded_features = rsc.decode(padded_features)[0]
  File "/home/bread98/.local/lib/python3.8/site-packages/reedsolo.py", line 940, in decode
    rmes, recc, errata_pos = rs_correct_msg(chunk, nsym, fcr=self.fcr, generator=self.generator, erase_pos=e_pos, only_erasures=only_erasures)
  File "/home/bread98/.local/lib/python3.8/site-packages/reedsolo.py", line 748, in rs_correct_msg
    err_loc = rs_find_error_locator(fsynd, nsym, erase_count=len(erase_pos))
  File "/home/bread98/.local/lib/python3.8/site-packages/reedsolo.py", line 659, in rs_find_error_locator
    raise ReedSolomonError("Too many errors to correct")
reedsolo.ReedSolomonError: Too many errors to correct

Wrong user!
-------------------------------------------------------------------------------------------------
Successfully authenticated!
8433616648366412438958958887441559189241222808507297180123304011037389908596951404223869173957125333028894189288458740593422692852440110628194254331790968
-------------------------------------------------------------------------------------------------



Successfully authenticated!
6941098263540159296821552447030292647684953454013231647331723707701392185541734121101764628650048190486422382503567946165547302408479553524062794684497382
-------------------------------------------------------------------------------------------------
Successfully authenticated!
6941098263540159296821552447030292647684953454013231647331723707701392185541734121101764628650048190486422382503567946165547302408479553524062794684497382
-------------------------------------------------------------------------------------------------
Successfully authenticated!
6941098263540159296821552447030292647684953454013231647331723707701392185541734121101764628650048190486422382503567946165547302408479553524062794684497382
-------------------------------------------------------------------------------------------------
Successfully authenticated!
6941098263540159296821552447030292647684953454013231647331723707701392185541734121101764628650048190486422382503567946165547302408479553524062794684497382
-------------------------------------------------------------------------------------------------



Successfully authenticated!
2380639141798689448349114681922327967873570989774379918849365376191724964433511111003714096529041503955423362151339210479502761393113741741602825664206853
-------------------------------------------------------------------------------------------------
Successfully authenticated!
2380639141798689448349114681922327967873570989774379918849365376191724964433511111003714096529041503955423362151339210479502761393113741741602825664206853
-------------------------------------------------------------------------------------------------
Successfully authenticated!
2380639141798689448349114681922327967873570989774379918849365376191724964433511111003714096529041503955423362151339210479502761393113741741602825664206853
-------------------------------------------------------------------------------------------------
Traceback (most recent call last):
  File "/mnt/c/BioMessages/reed_solomon/authentication.py", line 60, in authentication
    decoded_features = rsc.decode(padded_features)[0]
  File "/home/bread98/.local/lib/python3.8/site-packages/reedsolo.py", line 940, in decode
    rmes, recc, errata_pos = rs_correct_msg(chunk, nsym, fcr=self.fcr, generator=self.generator, erase_pos=e_pos, only_erasures=only_erasures)
  File "/home/bread98/.local/lib/python3.8/site-packages/reedsolo.py", line 748, in rs_correct_msg
    err_loc = rs_find_error_locator(fsynd, nsym, erase_count=len(erase_pos))
  File "/home/bread98/.local/lib/python3.8/site-packages/reedsolo.py", line 659, in rs_find_error_locator
    raise ReedSolomonError("Too many errors to correct")
reedsolo.ReedSolomonError: Too many errors to correct

Wrong user!
-------------------------------------------------------------------------------------------------



Successfully authenticated!
12152831846075592823712712907824833090415188428811643095214739137236724983594438373871952632146300925123922274457442175748070117600796160147017781400655109
-------------------------------------------------------------------------------------------------
Successfully authenticated!
12152831846075592823712712907824833090415188428811643095214739137236724983594438373871952632146300925123922274457442175748070117600796160147017781400655109
-------------------------------------------------------------------------------------------------
Successfully authenticated!
12152831846075592823712712907824833090415188428811643095214739137236724983594438373871952632146300925123922274457442175748070117600796160147017781400655109
-------------------------------------------------------------------------------------------------
Successfully authenticated!
12152831846075592823712712907824833090415188428811643095214739137236724983594438373871952632146300925123922274457442175748070117600796160147017781400655109
-------------------------------------------------------------------------------------------------



Successfully authenticated!
2524230458005253254689988817605511549872433041326413197863515978664347951333245225863403188606512290592653306067274979034082853434944034447530706472078499
-------------------------------------------------------------------------------------------------
Traceback (most recent call last):
  File "/mnt/c/BioMessages/reed_solomon/authentication.py", line 60, in authentication
    decoded_features = rsc.decode(padded_features)[0]
  File "/home/bread98/.local/lib/python3.8/site-packages/reedsolo.py", line 940, in decode
    rmes, recc, errata_pos = rs_correct_msg(chunk, nsym, fcr=self.fcr, generator=self.generator, erase_pos=e_pos, only_erasures=only_erasures)
  File "/home/bread98/.local/lib/python3.8/site-packages/reedsolo.py", line 748, in rs_correct_msg
    err_loc = rs_find_error_locator(fsynd, nsym, erase_count=len(erase_pos))
  File "/home/bread98/.local/lib/python3.8/site-packages/reedsolo.py", line 659, in rs_find_error_locator
    raise ReedSolomonError("Too many errors to correct")
reedsolo.ReedSolomonError: Too many errors to correct

Wrong user!
-------------------------------------------------------------------------------------------------
Successfully authenticated!
2524230458005253254689988817605511549872433041326413197863515978664347951333245225863403188606512290592653306067274979034082853434944034447530706472078499
-------------------------------------------------------------------------------------------------
Traceback (most recent call last):
  File "/mnt/c/BioMessages/reed_solomon/authentication.py", line 60, in authentication
    decoded_features = rsc.decode(padded_features)[0]
  File "/home/bread98/.local/lib/python3.8/site-packages/reedsolo.py", line 940, in decode
    rmes, recc, errata_pos = rs_correct_msg(chunk, nsym, fcr=self.fcr, generator=self.generator, erase_pos=e_pos, only_erasures=only_erasures)
  File "/home/bread98/.local/lib/python3.8/site-packages/reedsolo.py", line 748, in rs_correct_msg
    err_loc = rs_find_error_locator(fsynd, nsym, erase_count=len(erase_pos))
  File "/home/bread98/.local/lib/python3.8/site-packages/reedsolo.py", line 659, in rs_find_error_locator
    raise ReedSolomonError("Too many errors to correct")
reedsolo.ReedSolomonError: Too many errors to correct

Wrong user!
-------------------------------------------------------------------------------------------------



Successfully authenticated!
1711057769036313058576593013558194053178789982293519734296033615959935413188021445518663943316338660965230761174802508886032268914894202877255706655959403
-------------------------------------------------------------------------------------------------
Traceback (most recent call last):
  File "/mnt/c/BioMessages/reed_solomon/authentication.py", line 60, in authentication
    decoded_features = rsc.decode(padded_features)[0]
  File "/home/bread98/.local/lib/python3.8/site-packages/reedsolo.py", line 940, in decode
    rmes, recc, errata_pos = rs_correct_msg(chunk, nsym, fcr=self.fcr, generator=self.generator, erase_pos=e_pos, only_erasures=only_erasures)
  File "/home/bread98/.local/lib/python3.8/site-packages/reedsolo.py", line 748, in rs_correct_msg
    err_loc = rs_find_error_locator(fsynd, nsym, erase_count=len(erase_pos))
  File "/home/bread98/.local/lib/python3.8/site-packages/reedsolo.py", line 659, in rs_find_error_locator
    raise ReedSolomonError("Too many errors to correct")
reedsolo.ReedSolomonError: Too many errors to correct

Wrong user!
-------------------------------------------------------------------------------------------------
Traceback (most recent call last):
  File "/mnt/c/BioMessages/reed_solomon/authentication.py", line 60, in authentication
    decoded_features = rsc.decode(padded_features)[0]
  File "/home/bread98/.local/lib/python3.8/site-packages/reedsolo.py", line 940, in decode
    rmes, recc, errata_pos = rs_correct_msg(chunk, nsym, fcr=self.fcr, generator=self.generator, erase_pos=e_pos, only_erasures=only_erasures)
  File "/home/bread98/.local/lib/python3.8/site-packages/reedsolo.py", line 748, in rs_correct_msg
    err_loc = rs_find_error_locator(fsynd, nsym, erase_count=len(erase_pos))
  File "/home/bread98/.local/lib/python3.8/site-packages/reedsolo.py", line 659, in rs_find_error_locator
    raise ReedSolomonError("Too many errors to correct")
reedsolo.ReedSolomonError: Too many errors to correct

Wrong user!
-------------------------------------------------------------------------------------------------
Traceback (most recent call last):
  File "/mnt/c/BioMessages/reed_solomon/authentication.py", line 60, in authentication
    decoded_features = rsc.decode(padded_features)[0]
  File "/home/bread98/.local/lib/python3.8/site-packages/reedsolo.py", line 940, in decode
    rmes, recc, errata_pos = rs_correct_msg(chunk, nsym, fcr=self.fcr, generator=self.generator, erase_pos=e_pos, only_erasures=only_erasures)
  File "/home/bread98/.local/lib/python3.8/site-packages/reedsolo.py", line 750, in rs_correct_msg
    err_pos = rs_find_errors(err_loc[::-1], len(msg_out), generator)
  File "/home/bread98/.local/lib/python3.8/site-packages/reedsolo.py", line 694, in rs_find_errors
    raise ReedSolomonError("Too many (or few) errors found by Chien Search for the errata locator polynomial!")
reedsolo.ReedSolomonError: Too many (or few) errors found by Chien Search for the errata locator polynomial!

Wrong user!
-------------------------------------------------------------------------------------------------



Successfully authenticated!
1099318835556490828203069679511542808466222082800967660644147811600022660371111405750803740449639668602139895531319833877216020130912569354098656881392383
-------------------------------------------------------------------------------------------------
Traceback (most recent call last):
  File "/mnt/c/BioMessages/reed_solomon/authentication.py", line 60, in authentication
    decoded_features = rsc.decode(padded_features)[0]
  File "/home/bread98/.local/lib/python3.8/site-packages/reedsolo.py", line 940, in decode
    rmes, recc, errata_pos = rs_correct_msg(chunk, nsym, fcr=self.fcr, generator=self.generator, erase_pos=e_pos, only_erasures=only_erasures)
  File "/home/bread98/.local/lib/python3.8/site-packages/reedsolo.py", line 748, in rs_correct_msg
    err_loc = rs_find_error_locator(fsynd, nsym, erase_count=len(erase_pos))
  File "/home/bread98/.local/lib/python3.8/site-packages/reedsolo.py", line 659, in rs_find_error_locator
    raise ReedSolomonError("Too many errors to correct")
reedsolo.ReedSolomonError: Too many errors to correct

Wrong user!
-------------------------------------------------------------------------------------------------
Successfully authenticated!
1099318835556490828203069679511542808466222082800967660644147811600022660371111405750803740449639668602139895531319833877216020130912569354098656881392383
-------------------------------------------------------------------------------------------------
Traceback (most recent call last):
  File "/mnt/c/BioMessages/reed_solomon/authentication.py", line 60, in authentication
    decoded_features = rsc.decode(padded_features)[0]
  File "/home/bread98/.local/lib/python3.8/site-packages/reedsolo.py", line 940, in decode
    rmes, recc, errata_pos = rs_correct_msg(chunk, nsym, fcr=self.fcr, generator=self.generator, erase_pos=e_pos, only_erasures=only_erasures)
  File "/home/bread98/.local/lib/python3.8/site-packages/reedsolo.py", line 748, in rs_correct_msg
    err_loc = rs_find_error_locator(fsynd, nsym, erase_count=len(erase_pos))
  File "/home/bread98/.local/lib/python3.8/site-packages/reedsolo.py", line 659, in rs_find_error_locator
    raise ReedSolomonError("Too many errors to correct")
reedsolo.ReedSolomonError: Too many errors to correct

Wrong user!
-------------------------------------------------------------------------------------------------



Successfully authenticated!
13370447090441680808265594451339942451546506419249271326447788508431192251104277448460915235664180932893342956241896971573876235616434597369849151048078896
-------------------------------------------------------------------------------------------------
Traceback (most recent call last):
  File "/mnt/c/BioMessages/reed_solomon/authentication.py", line 60, in authentication
    decoded_features = rsc.decode(padded_features)[0]
  File "/home/bread98/.local/lib/python3.8/site-packages/reedsolo.py", line 940, in decode
    rmes, recc, errata_pos = rs_correct_msg(chunk, nsym, fcr=self.fcr, generator=self.generator, erase_pos=e_pos, only_erasures=only_erasures)
  File "/home/bread98/.local/lib/python3.8/site-packages/reedsolo.py", line 748, in rs_correct_msg
    err_loc = rs_find_error_locator(fsynd, nsym, erase_count=len(erase_pos))
  File "/home/bread98/.local/lib/python3.8/site-packages/reedsolo.py", line 659, in rs_find_error_locator
    raise ReedSolomonError("Too many errors to correct")
reedsolo.ReedSolomonError: Too many errors to correct

Wrong user!
-------------------------------------------------------------------------------------------------
Traceback (most recent call last):
  File "/mnt/c/BioMessages/reed_solomon/authentication.py", line 60, in authentication
    decoded_features = rsc.decode(padded_features)[0]
  File "/home/bread98/.local/lib/python3.8/site-packages/reedsolo.py", line 940, in decode
    rmes, recc, errata_pos = rs_correct_msg(chunk, nsym, fcr=self.fcr, generator=self.generator, erase_pos=e_pos, only_erasures=only_erasures)
  File "/home/bread98/.local/lib/python3.8/site-packages/reedsolo.py", line 748, in rs_correct_msg
    err_loc = rs_find_error_locator(fsynd, nsym, erase_count=len(erase_pos))
  File "/home/bread98/.local/lib/python3.8/site-packages/reedsolo.py", line 659, in rs_find_error_locator
    raise ReedSolomonError("Too many errors to correct")
reedsolo.ReedSolomonError: Too many errors to correct

Wrong user!
-------------------------------------------------------------------------------------------------
Successfully authenticated!
13370447090441680808265594451339942451546506419249271326447788508431192251104277448460915235664180932893342956241896971573876235616434597369849151048078896
-------------------------------------------------------------------------------------------------



Successfully authenticated!
2075091835505222710822822125081450661501529184530583805983369967402793948253771590219853196579786592407414798108653441120780834408264374539305368606479533
-------------------------------------------------------------------------------------------------
Traceback (most recent call last):
  File "/mnt/c/BioMessages/reed_solomon/authentication.py", line 60, in authentication
    decoded_features = rsc.decode(padded_features)[0]
  File "/home/bread98/.local/lib/python3.8/site-packages/reedsolo.py", line 940, in decode
    rmes, recc, errata_pos = rs_correct_msg(chunk, nsym, fcr=self.fcr, generator=self.generator, erase_pos=e_pos, only_erasures=only_erasures)
  File "/home/bread98/.local/lib/python3.8/site-packages/reedsolo.py", line 748, in rs_correct_msg
    err_loc = rs_find_error_locator(fsynd, nsym, erase_count=len(erase_pos))
  File "/home/bread98/.local/lib/python3.8/site-packages/reedsolo.py", line 659, in rs_find_error_locator
    raise ReedSolomonError("Too many errors to correct")
reedsolo.ReedSolomonError: Too many errors to correct

Wrong user!
-------------------------------------------------------------------------------------------------
Successfully authenticated!
2075091835505222710822822125081450661501529184530583805983369967402793948253771590219853196579786592407414798108653441120780834408264374539305368606479533
-------------------------------------------------------------------------------------------------
Successfully authenticated!
2075091835505222710822822125081450661501529184530583805983369967402793948253771590219853196579786592407414798108653441120780834408264374539305368606479533
-------------------------------------------------------------------------------------------------



Successfully authenticated!
5410186215117394658162218654473868131927473637488834774990009819417258859500256437392036090734848176165169827969698050844821634568928466089029477247639021
-------------------------------------------------------------------------------------------------
Traceback (most recent call last):
  File "/mnt/c/BioMessages/reed_solomon/authentication.py", line 60, in authentication
    decoded_features = rsc.decode(padded_features)[0]
  File "/home/bread98/.local/lib/python3.8/site-packages/reedsolo.py", line 940, in decode
    rmes, recc, errata_pos = rs_correct_msg(chunk, nsym, fcr=self.fcr, generator=self.generator, erase_pos=e_pos, only_erasures=only_erasures)
  File "/home/bread98/.local/lib/python3.8/site-packages/reedsolo.py", line 748, in rs_correct_msg
    err_loc = rs_find_error_locator(fsynd, nsym, erase_count=len(erase_pos))
  File "/home/bread98/.local/lib/python3.8/site-packages/reedsolo.py", line 659, in rs_find_error_locator
    raise ReedSolomonError("Too many errors to correct")
reedsolo.ReedSolomonError: Too many errors to correct

Wrong user!
-------------------------------------------------------------------------------------------------
Successfully authenticated!
5410186215117394658162218654473868131927473637488834774990009819417258859500256437392036090734848176165169827969698050844821634568928466089029477247639021
-------------------------------------------------------------------------------------------------
Traceback (most recent call last):
  File "/mnt/c/BioMessages/reed_solomon/authentication.py", line 60, in authentication
    decoded_features = rsc.decode(padded_features)[0]
  File "/home/bread98/.local/lib/python3.8/site-packages/reedsolo.py", line 940, in decode
    rmes, recc, errata_pos = rs_correct_msg(chunk, nsym, fcr=self.fcr, generator=self.generator, erase_pos=e_pos, only_erasures=only_erasures)
  File "/home/bread98/.local/lib/python3.8/site-packages/reedsolo.py", line 748, in rs_correct_msg
    err_loc = rs_find_error_locator(fsynd, nsym, erase_count=len(erase_pos))
  File "/home/bread98/.local/lib/python3.8/site-packages/reedsolo.py", line 659, in rs_find_error_locator
    raise ReedSolomonError("Too many errors to correct")
reedsolo.ReedSolomonError: Too many errors to correct

Wrong user!
-------------------------------------------------------------------------------------------------



Successfully authenticated!
10032295295026469675384558319442979205556104033060646517397407307122348771669947456700607913484156583554281738492885521336160321061122482491535323049341063
-------------------------------------------------------------------------------------------------
Successfully authenticated!
10032295295026469675384558319442979205556104033060646517397407307122348771669947456700607913484156583554281738492885521336160321061122482491535323049341063
-------------------------------------------------------------------------------------------------
Successfully authenticated!
10032295295026469675384558319442979205556104033060646517397407307122348771669947456700607913484156583554281738492885521336160321061122482491535323049341063
-------------------------------------------------------------------------------------------------
Successfully authenticated!
10032295295026469675384558319442979205556104033060646517397407307122348771669947456700607913484156583554281738492885521336160321061122482491535323049341063
-------------------------------------------------------------------------------------------------



Successfully authenticated!
8871434344817540992862966510006887208377599619442898368732532695389135848138042029535485051370263689407648920406231490572527171836084490736670509052263821
-------------------------------------------------------------------------------------------------
Traceback (most recent call last):
  File "/mnt/c/BioMessages/reed_solomon/authentication.py", line 60, in authentication
    decoded_features = rsc.decode(padded_features)[0]
  File "/home/bread98/.local/lib/python3.8/site-packages/reedsolo.py", line 940, in decode
    rmes, recc, errata_pos = rs_correct_msg(chunk, nsym, fcr=self.fcr, generator=self.generator, erase_pos=e_pos, only_erasures=only_erasures)
  File "/home/bread98/.local/lib/python3.8/site-packages/reedsolo.py", line 748, in rs_correct_msg
    err_loc = rs_find_error_locator(fsynd, nsym, erase_count=len(erase_pos))
  File "/home/bread98/.local/lib/python3.8/site-packages/reedsolo.py", line 659, in rs_find_error_locator
    raise ReedSolomonError("Too many errors to correct")
reedsolo.ReedSolomonError: Too many errors to correct

Wrong user!
-------------------------------------------------------------------------------------------------
Traceback (most recent call last):
  File "/mnt/c/BioMessages/reed_solomon/authentication.py", line 60, in authentication
    decoded_features = rsc.decode(padded_features)[0]
  File "/home/bread98/.local/lib/python3.8/site-packages/reedsolo.py", line 940, in decode
    rmes, recc, errata_pos = rs_correct_msg(chunk, nsym, fcr=self.fcr, generator=self.generator, erase_pos=e_pos, only_erasures=only_erasures)
  File "/home/bread98/.local/lib/python3.8/site-packages/reedsolo.py", line 748, in rs_correct_msg
    err_loc = rs_find_error_locator(fsynd, nsym, erase_count=len(erase_pos))
  File "/home/bread98/.local/lib/python3.8/site-packages/reedsolo.py", line 659, in rs_find_error_locator
    raise ReedSolomonError("Too many errors to correct")
reedsolo.ReedSolomonError: Too many errors to correct

Wrong user!
-------------------------------------------------------------------------------------------------
Traceback (most recent call last):
  File "/mnt/c/BioMessages/reed_solomon/authentication.py", line 60, in authentication
    decoded_features = rsc.decode(padded_features)[0]
  File "/home/bread98/.local/lib/python3.8/site-packages/reedsolo.py", line 940, in decode
    rmes, recc, errata_pos = rs_correct_msg(chunk, nsym, fcr=self.fcr, generator=self.generator, erase_pos=e_pos, only_erasures=only_erasures)
  File "/home/bread98/.local/lib/python3.8/site-packages/reedsolo.py", line 748, in rs_correct_msg
    err_loc = rs_find_error_locator(fsynd, nsym, erase_count=len(erase_pos))
  File "/home/bread98/.local/lib/python3.8/site-packages/reedsolo.py", line 659, in rs_find_error_locator
    raise ReedSolomonError("Too many errors to correct")
reedsolo.ReedSolomonError: Too many errors to correct

Wrong user!
-------------------------------------------------------------------------------------------------



Successfully authenticated!
3589024265798578079973071736758506318289372597642461644550953210007506264210227746484588402981908191155028892194331796896870590654795630577945656924117301
-------------------------------------------------------------------------------------------------
Traceback (most recent call last):
  File "/mnt/c/BioMessages/reed_solomon/authentication.py", line 60, in authentication
    decoded_features = rsc.decode(padded_features)[0]
  File "/home/bread98/.local/lib/python3.8/site-packages/reedsolo.py", line 940, in decode
    rmes, recc, errata_pos = rs_correct_msg(chunk, nsym, fcr=self.fcr, generator=self.generator, erase_pos=e_pos, only_erasures=only_erasures)
  File "/home/bread98/.local/lib/python3.8/site-packages/reedsolo.py", line 748, in rs_correct_msg
    err_loc = rs_find_error_locator(fsynd, nsym, erase_count=len(erase_pos))
  File "/home/bread98/.local/lib/python3.8/site-packages/reedsolo.py", line 659, in rs_find_error_locator
    raise ReedSolomonError("Too many errors to correct")
reedsolo.ReedSolomonError: Too many errors to correct

Wrong user!
-------------------------------------------------------------------------------------------------
Successfully authenticated!
3589024265798578079973071736758506318289372597642461644550953210007506264210227746484588402981908191155028892194331796896870590654795630577945656924117301
-------------------------------------------------------------------------------------------------
Traceback (most recent call last):
  File "/mnt/c/BioMessages/reed_solomon/authentication.py", line 60, in authentication
    decoded_features = rsc.decode(padded_features)[0]
  File "/home/bread98/.local/lib/python3.8/site-packages/reedsolo.py", line 940, in decode
    rmes, recc, errata_pos = rs_correct_msg(chunk, nsym, fcr=self.fcr, generator=self.generator, erase_pos=e_pos, only_erasures=only_erasures)
  File "/home/bread98/.local/lib/python3.8/site-packages/reedsolo.py", line 748, in rs_correct_msg
    err_loc = rs_find_error_locator(fsynd, nsym, erase_count=len(erase_pos))
  File "/home/bread98/.local/lib/python3.8/site-packages/reedsolo.py", line 659, in rs_find_error_locator
    raise ReedSolomonError("Too many errors to correct")
reedsolo.ReedSolomonError: Too many errors to correct

Wrong user!
-------------------------------------------------------------------------------------------------



Successfully authenticated!
1895746290770213541116471201462806588408393529722921903367350336872517552576833890747529211344042796507018814056537833228392849115547262209527104583283045
-------------------------------------------------------------------------------------------------
Successfully authenticated!
1895746290770213541116471201462806588408393529722921903367350336872517552576833890747529211344042796507018814056537833228392849115547262209527104583283045
-------------------------------------------------------------------------------------------------
Successfully authenticated!
1895746290770213541116471201462806588408393529722921903367350336872517552576833890747529211344042796507018814056537833228392849115547262209527104583283045
-------------------------------------------------------------------------------------------------
Traceback (most recent call last):
  File "/mnt/c/BioMessages/reed_solomon/authentication.py", line 60, in authentication
    decoded_features = rsc.decode(padded_features)[0]
  File "/home/bread98/.local/lib/python3.8/site-packages/reedsolo.py", line 940, in decode
    rmes, recc, errata_pos = rs_correct_msg(chunk, nsym, fcr=self.fcr, generator=self.generator, erase_pos=e_pos, only_erasures=only_erasures)
  File "/home/bread98/.local/lib/python3.8/site-packages/reedsolo.py", line 748, in rs_correct_msg
    err_loc = rs_find_error_locator(fsynd, nsym, erase_count=len(erase_pos))
  File "/home/bread98/.local/lib/python3.8/site-packages/reedsolo.py", line 659, in rs_find_error_locator
    raise ReedSolomonError("Too many errors to correct")
reedsolo.ReedSolomonError: Too many errors to correct

Wrong user!
-------------------------------------------------------------------------------------------------



Successfully authenticated!
2717804119290532522410847108159258086480869929744449805594960024376167438309113217504172284058280040438163828217862210763588735725804737443224687875240916
-------------------------------------------------------------------------------------------------
Traceback (most recent call last):
  File "/mnt/c/BioMessages/reed_solomon/authentication.py", line 60, in authentication
    decoded_features = rsc.decode(padded_features)[0]
  File "/home/bread98/.local/lib/python3.8/site-packages/reedsolo.py", line 940, in decode
    rmes, recc, errata_pos = rs_correct_msg(chunk, nsym, fcr=self.fcr, generator=self.generator, erase_pos=e_pos, only_erasures=only_erasures)
  File "/home/bread98/.local/lib/python3.8/site-packages/reedsolo.py", line 748, in rs_correct_msg
    err_loc = rs_find_error_locator(fsynd, nsym, erase_count=len(erase_pos))
  File "/home/bread98/.local/lib/python3.8/site-packages/reedsolo.py", line 659, in rs_find_error_locator
    raise ReedSolomonError("Too many errors to correct")
reedsolo.ReedSolomonError: Too many errors to correct

Wrong user!
-------------------------------------------------------------------------------------------------
Traceback (most recent call last):
  File "/mnt/c/BioMessages/reed_solomon/authentication.py", line 60, in authentication
    decoded_features = rsc.decode(padded_features)[0]
  File "/home/bread98/.local/lib/python3.8/site-packages/reedsolo.py", line 940, in decode
    rmes, recc, errata_pos = rs_correct_msg(chunk, nsym, fcr=self.fcr, generator=self.generator, erase_pos=e_pos, only_erasures=only_erasures)
  File "/home/bread98/.local/lib/python3.8/site-packages/reedsolo.py", line 748, in rs_correct_msg
    err_loc = rs_find_error_locator(fsynd, nsym, erase_count=len(erase_pos))
  File "/home/bread98/.local/lib/python3.8/site-packages/reedsolo.py", line 659, in rs_find_error_locator
    raise ReedSolomonError("Too many errors to correct")
reedsolo.ReedSolomonError: Too many errors to correct

Wrong user!
-------------------------------------------------------------------------------------------------
Successfully authenticated!
2717804119290532522410847108159258086480869929744449805594960024376167438309113217504172284058280040438163828217862210763588735725804737443224687875240916
-------------------------------------------------------------------------------------------------



Successfully authenticated!
12421440377921938439938783894885089690428289199254479939022001960716252251479339666818155050457044710899743322047575234853342173074546100177108512925985570
-------------------------------------------------------------------------------------------------
Traceback (most recent call last):
  File "/mnt/c/BioMessages/reed_solomon/authentication.py", line 60, in authentication
    decoded_features = rsc.decode(padded_features)[0]
  File "/home/bread98/.local/lib/python3.8/site-packages/reedsolo.py", line 940, in decode
    rmes, recc, errata_pos = rs_correct_msg(chunk, nsym, fcr=self.fcr, generator=self.generator, erase_pos=e_pos, only_erasures=only_erasures)
  File "/home/bread98/.local/lib/python3.8/site-packages/reedsolo.py", line 748, in rs_correct_msg
    err_loc = rs_find_error_locator(fsynd, nsym, erase_count=len(erase_pos))
  File "/home/bread98/.local/lib/python3.8/site-packages/reedsolo.py", line 659, in rs_find_error_locator
    raise ReedSolomonError("Too many errors to correct")
reedsolo.ReedSolomonError: Too many errors to correct

Wrong user!
-------------------------------------------------------------------------------------------------
Successfully authenticated!
12421440377921938439938783894885089690428289199254479939022001960716252251479339666818155050457044710899743322047575234853342173074546100177108512925985570
-------------------------------------------------------------------------------------------------
Successfully authenticated!
12421440377921938439938783894885089690428289199254479939022001960716252251479339666818155050457044710899743322047575234853342173074546100177108512925985570
-------------------------------------------------------------------------------------------------



Successfully authenticated!
12999923154764324327923575600095710946994309723271242960689402886271819451525179290665797767294190527078628713829305596336144015188344774400796909240934210
-------------------------------------------------------------------------------------------------
Successfully authenticated!
12999923154764324327923575600095710946994309723271242960689402886271819451525179290665797767294190527078628713829305596336144015188344774400796909240934210
-------------------------------------------------------------------------------------------------
Traceback (most recent call last):
  File "/mnt/c/BioMessages/reed_solomon/authentication.py", line 60, in authentication
    decoded_features = rsc.decode(padded_features)[0]
  File "/home/bread98/.local/lib/python3.8/site-packages/reedsolo.py", line 940, in decode
    rmes, recc, errata_pos = rs_correct_msg(chunk, nsym, fcr=self.fcr, generator=self.generator, erase_pos=e_pos, only_erasures=only_erasures)
  File "/home/bread98/.local/lib/python3.8/site-packages/reedsolo.py", line 748, in rs_correct_msg
    err_loc = rs_find_error_locator(fsynd, nsym, erase_count=len(erase_pos))
  File "/home/bread98/.local/lib/python3.8/site-packages/reedsolo.py", line 659, in rs_find_error_locator
    raise ReedSolomonError("Too many errors to correct")
reedsolo.ReedSolomonError: Too many errors to correct

Wrong user!
-------------------------------------------------------------------------------------------------
Successfully authenticated!
12999923154764324327923575600095710946994309723271242960689402886271819451525179290665797767294190527078628713829305596336144015188344774400796909240934210
-------------------------------------------------------------------------------------------------



Successfully authenticated!
3637278188708151768027005076092236149680929547770863186337585452297132172755256722253486507294901397511035176790857758406714489655247468521783423777547409
-------------------------------------------------------------------------------------------------
Successfully authenticated!
3637278188708151768027005076092236149680929547770863186337585452297132172755256722253486507294901397511035176790857758406714489655247468521783423777547409
-------------------------------------------------------------------------------------------------
Successfully authenticated!
3637278188708151768027005076092236149680929547770863186337585452297132172755256722253486507294901397511035176790857758406714489655247468521783423777547409
-------------------------------------------------------------------------------------------------
Successfully authenticated!
3637278188708151768027005076092236149680929547770863186337585452297132172755256722253486507294901397511035176790857758406714489655247468521783423777547409
-------------------------------------------------------------------------------------------------



Successfully authenticated!
6863300796160226420660430371450865412187396867535628274791369633879058621836956098213846645016994931860400293605382127722664325605091330328295376219885164
-------------------------------------------------------------------------------------------------
Successfully authenticated!
6863300796160226420660430371450865412187396867535628274791369633879058621836956098213846645016994931860400293605382127722664325605091330328295376219885164
-------------------------------------------------------------------------------------------------
Successfully authenticated!
6863300796160226420660430371450865412187396867535628274791369633879058621836956098213846645016994931860400293605382127722664325605091330328295376219885164
-------------------------------------------------------------------------------------------------
Traceback (most recent call last):
  File "/mnt/c/BioMessages/reed_solomon/authentication.py", line 60, in authentication
    decoded_features = rsc.decode(padded_features)[0]
  File "/home/bread98/.local/lib/python3.8/site-packages/reedsolo.py", line 940, in decode
    rmes, recc, errata_pos = rs_correct_msg(chunk, nsym, fcr=self.fcr, generator=self.generator, erase_pos=e_pos, only_erasures=only_erasures)
  File "/home/bread98/.local/lib/python3.8/site-packages/reedsolo.py", line 748, in rs_correct_msg
    err_loc = rs_find_error_locator(fsynd, nsym, erase_count=len(erase_pos))
  File "/home/bread98/.local/lib/python3.8/site-packages/reedsolo.py", line 659, in rs_find_error_locator
    raise ReedSolomonError("Too many errors to correct")
reedsolo.ReedSolomonError: Too many errors to correct

Wrong user!
-------------------------------------------------------------------------------------------------



Successfully authenticated!
12424824786851406385750462522417563896967766501150436997222832039497716660942248882356244589069109299714587055617767600793865127673677407693787245443417278
-------------------------------------------------------------------------------------------------
Traceback (most recent call last):
  File "/mnt/c/BioMessages/reed_solomon/authentication.py", line 60, in authentication
    decoded_features = rsc.decode(padded_features)[0]
  File "/home/bread98/.local/lib/python3.8/site-packages/reedsolo.py", line 940, in decode
    rmes, recc, errata_pos = rs_correct_msg(chunk, nsym, fcr=self.fcr, generator=self.generator, erase_pos=e_pos, only_erasures=only_erasures)
  File "/home/bread98/.local/lib/python3.8/site-packages/reedsolo.py", line 748, in rs_correct_msg
    err_loc = rs_find_error_locator(fsynd, nsym, erase_count=len(erase_pos))
  File "/home/bread98/.local/lib/python3.8/site-packages/reedsolo.py", line 659, in rs_find_error_locator
    raise ReedSolomonError("Too many errors to correct")
reedsolo.ReedSolomonError: Too many errors to correct

Wrong user!
-------------------------------------------------------------------------------------------------
Successfully authenticated!
12424824786851406385750462522417563896967766501150436997222832039497716660942248882356244589069109299714587055617767600793865127673677407693787245443417278
-------------------------------------------------------------------------------------------------
Successfully authenticated!
12424824786851406385750462522417563896967766501150436997222832039497716660942248882356244589069109299714587055617767600793865127673677407693787245443417278
-------------------------------------------------------------------------------------------------



Successfully authenticated!
68289745416698745459024594661938567028786032029057674415844034670254113679877224307026420155321956515420702839713475445868838784918037589476376795016962
-------------------------------------------------------------------------------------------------
Successfully authenticated!
68289745416698745459024594661938567028786032029057674415844034670254113679877224307026420155321956515420702839713475445868838784918037589476376795016962
-------------------------------------------------------------------------------------------------
Successfully authenticated!
68289745416698745459024594661938567028786032029057674415844034670254113679877224307026420155321956515420702839713475445868838784918037589476376795016962
-------------------------------------------------------------------------------------------------
Successfully authenticated!
68289745416698745459024594661938567028786032029057674415844034670254113679877224307026420155321956515420702839713475445868838784918037589476376795016962
-------------------------------------------------------------------------------------------------



Successfully authenticated!
855844583504277849868785295803679320765481050815049055862574600741988820825637720163411719224160013111341134715597437903273621631019224253863126364404772
-------------------------------------------------------------------------------------------------
Successfully authenticated!
855844583504277849868785295803679320765481050815049055862574600741988820825637720163411719224160013111341134715597437903273621631019224253863126364404772
-------------------------------------------------------------------------------------------------
Traceback (most recent call last):
  File "/mnt/c/BioMessages/reed_solomon/authentication.py", line 60, in authentication
    decoded_features = rsc.decode(padded_features)[0]
  File "/home/bread98/.local/lib/python3.8/site-packages/reedsolo.py", line 940, in decode
    rmes, recc, errata_pos = rs_correct_msg(chunk, nsym, fcr=self.fcr, generator=self.generator, erase_pos=e_pos, only_erasures=only_erasures)
  File "/home/bread98/.local/lib/python3.8/site-packages/reedsolo.py", line 748, in rs_correct_msg
    err_loc = rs_find_error_locator(fsynd, nsym, erase_count=len(erase_pos))
  File "/home/bread98/.local/lib/python3.8/site-packages/reedsolo.py", line 659, in rs_find_error_locator
    raise ReedSolomonError("Too many errors to correct")
reedsolo.ReedSolomonError: Too many errors to correct

Wrong user!
-------------------------------------------------------------------------------------------------
Successfully authenticated!
855844583504277849868785295803679320765481050815049055862574600741988820825637720163411719224160013111341134715597437903273621631019224253863126364404772
-------------------------------------------------------------------------------------------------



Successfully authenticated!
1358725809168138553567431744862664699196441833347010772942161327457353218681155940691922292211812442431965997506721374559165684278932613213893848734226868
-------------------------------------------------------------------------------------------------
Successfully authenticated!
1358725809168138553567431744862664699196441833347010772942161327457353218681155940691922292211812442431965997506721374559165684278932613213893848734226868
-------------------------------------------------------------------------------------------------
Successfully authenticated!
1358725809168138553567431744862664699196441833347010772942161327457353218681155940691922292211812442431965997506721374559165684278932613213893848734226868
-------------------------------------------------------------------------------------------------
Successfully authenticated!
1358725809168138553567431744862664699196441833347010772942161327457353218681155940691922292211812442431965997506721374559165684278932613213893848734226868
-------------------------------------------------------------------------------------------------



Successfully authenticated!
5861969714673492319303610416363535792625302745498613733130020113149782205209858211738351245165627653160124812236496313189918199318480806109174133853225669
-------------------------------------------------------------------------------------------------
Successfully authenticated!
5861969714673492319303610416363535792625302745498613733130020113149782205209858211738351245165627653160124812236496313189918199318480806109174133853225669
-------------------------------------------------------------------------------------------------
Successfully authenticated!
5861969714673492319303610416363535792625302745498613733130020113149782205209858211738351245165627653160124812236496313189918199318480806109174133853225669
-------------------------------------------------------------------------------------------------
Successfully authenticated!
5861969714673492319303610416363535792625302745498613733130020113149782205209858211738351245165627653160124812236496313189918199318480806109174133853225669
-------------------------------------------------------------------------------------------------



Successfully authenticated!
814776154075522964995368690674594680345525829532969211323072661920494998949021504191051733305590908131643391664169315563895759274286800564507837454213399
-------------------------------------------------------------------------------------------------
Successfully authenticated!
814776154075522964995368690674594680345525829532969211323072661920494998949021504191051733305590908131643391664169315563895759274286800564507837454213399
-------------------------------------------------------------------------------------------------
Successfully authenticated!
814776154075522964995368690674594680345525829532969211323072661920494998949021504191051733305590908131643391664169315563895759274286800564507837454213399
-------------------------------------------------------------------------------------------------
Successfully authenticated!
814776154075522964995368690674594680345525829532969211323072661920494998949021504191051733305590908131643391664169315563895759274286800564507837454213399
-------------------------------------------------------------------------------------------------



Successfully authenticated!
13179122205097455463086124809189922308161511902312712486021247620847590625303653462619413650227020747414660434583599054697139956168918401173980429221339958
-------------------------------------------------------------------------------------------------
Traceback (most recent call last):
  File "/mnt/c/BioMessages/reed_solomon/authentication.py", line 60, in authentication
    decoded_features = rsc.decode(padded_features)[0]
  File "/home/bread98/.local/lib/python3.8/site-packages/reedsolo.py", line 940, in decode
    rmes, recc, errata_pos = rs_correct_msg(chunk, nsym, fcr=self.fcr, generator=self.generator, erase_pos=e_pos, only_erasures=only_erasures)
  File "/home/bread98/.local/lib/python3.8/site-packages/reedsolo.py", line 748, in rs_correct_msg
    err_loc = rs_find_error_locator(fsynd, nsym, erase_count=len(erase_pos))
  File "/home/bread98/.local/lib/python3.8/site-packages/reedsolo.py", line 659, in rs_find_error_locator
    raise ReedSolomonError("Too many errors to correct")
reedsolo.ReedSolomonError: Too many errors to correct

Wrong user!
-------------------------------------------------------------------------------------------------
Successfully authenticated!
13179122205097455463086124809189922308161511902312712486021247620847590625303653462619413650227020747414660434583599054697139956168918401173980429221339958
-------------------------------------------------------------------------------------------------
Traceback (most recent call last):
  File "/mnt/c/BioMessages/reed_solomon/authentication.py", line 60, in authentication
    decoded_features = rsc.decode(padded_features)[0]
  File "/home/bread98/.local/lib/python3.8/site-packages/reedsolo.py", line 940, in decode
    rmes, recc, errata_pos = rs_correct_msg(chunk, nsym, fcr=self.fcr, generator=self.generator, erase_pos=e_pos, only_erasures=only_erasures)
  File "/home/bread98/.local/lib/python3.8/site-packages/reedsolo.py", line 748, in rs_correct_msg
    err_loc = rs_find_error_locator(fsynd, nsym, erase_count=len(erase_pos))
  File "/home/bread98/.local/lib/python3.8/site-packages/reedsolo.py", line 659, in rs_find_error_locator
    raise ReedSolomonError("Too many errors to correct")
reedsolo.ReedSolomonError: Too many errors to correct

Wrong user!
-------------------------------------------------------------------------------------------------



Successfully authenticated!
2821868638003555269003754369003663346839651861859830279932497679018507407281333208402811625581296960438310369934674265140899519598362150676338048181061402
-------------------------------------------------------------------------------------------------
Traceback (most recent call last):
  File "/mnt/c/BioMessages/reed_solomon/authentication.py", line 60, in authentication
    decoded_features = rsc.decode(padded_features)[0]
  File "/home/bread98/.local/lib/python3.8/site-packages/reedsolo.py", line 940, in decode
    rmes, recc, errata_pos = rs_correct_msg(chunk, nsym, fcr=self.fcr, generator=self.generator, erase_pos=e_pos, only_erasures=only_erasures)
  File "/home/bread98/.local/lib/python3.8/site-packages/reedsolo.py", line 748, in rs_correct_msg
    err_loc = rs_find_error_locator(fsynd, nsym, erase_count=len(erase_pos))
  File "/home/bread98/.local/lib/python3.8/site-packages/reedsolo.py", line 659, in rs_find_error_locator
    raise ReedSolomonError("Too many errors to correct")
reedsolo.ReedSolomonError: Too many errors to correct

Wrong user!
-------------------------------------------------------------------------------------------------
Successfully authenticated!
2821868638003555269003754369003663346839651861859830279932497679018507407281333208402811625581296960438310369934674265140899519598362150676338048181061402
-------------------------------------------------------------------------------------------------
Successfully authenticated!
2821868638003555269003754369003663346839651861859830279932497679018507407281333208402811625581296960438310369934674265140899519598362150676338048181061402
-------------------------------------------------------------------------------------------------



Successfully authenticated!
13101170478404925615600829720315870151665039083582948469947776118721407567532327133050598582688605197725663456539605303775466848806511194539706238120476407
-------------------------------------------------------------------------------------------------
Successfully authenticated!
13101170478404925615600829720315870151665039083582948469947776118721407567532327133050598582688605197725663456539605303775466848806511194539706238120476407
-------------------------------------------------------------------------------------------------
Successfully authenticated!
13101170478404925615600829720315870151665039083582948469947776118721407567532327133050598582688605197725663456539605303775466848806511194539706238120476407
-------------------------------------------------------------------------------------------------
Traceback (most recent call last):
  File "/mnt/c/BioMessages/reed_solomon/authentication.py", line 60, in authentication
    decoded_features = rsc.decode(padded_features)[0]
  File "/home/bread98/.local/lib/python3.8/site-packages/reedsolo.py", line 940, in decode
    rmes, recc, errata_pos = rs_correct_msg(chunk, nsym, fcr=self.fcr, generator=self.generator, erase_pos=e_pos, only_erasures=only_erasures)
  File "/home/bread98/.local/lib/python3.8/site-packages/reedsolo.py", line 748, in rs_correct_msg
    err_loc = rs_find_error_locator(fsynd, nsym, erase_count=len(erase_pos))
  File "/home/bread98/.local/lib/python3.8/site-packages/reedsolo.py", line 659, in rs_find_error_locator
    raise ReedSolomonError("Too many errors to correct")
reedsolo.ReedSolomonError: Too many errors to correct

Wrong user!
-------------------------------------------------------------------------------------------------



Successfully authenticated!
9638040331426023840134981105585620693944645460099675197101511032191008054063365564512390890291093114605774173250469286031256132763795097659320777924977778
-------------------------------------------------------------------------------------------------
Successfully authenticated!
9638040331426023840134981105585620693944645460099675197101511032191008054063365564512390890291093114605774173250469286031256132763795097659320777924977778
-------------------------------------------------------------------------------------------------
Successfully authenticated!
9638040331426023840134981105585620693944645460099675197101511032191008054063365564512390890291093114605774173250469286031256132763795097659320777924977778
-------------------------------------------------------------------------------------------------
Successfully authenticated!
9638040331426023840134981105585620693944645460099675197101511032191008054063365564512390890291093114605774173250469286031256132763795097659320777924977778
-------------------------------------------------------------------------------------------------



Successfully authenticated!
935240463652256025794823299972456187812131303290734112778263851637032639920875988460942423300139058580206820326026139265023611750608163596997857708189184
-------------------------------------------------------------------------------------------------
Successfully authenticated!
935240463652256025794823299972456187812131303290734112778263851637032639920875988460942423300139058580206820326026139265023611750608163596997857708189184
-------------------------------------------------------------------------------------------------
Traceback (most recent call last):
  File "/mnt/c/BioMessages/reed_solomon/authentication.py", line 60, in authentication
    decoded_features = rsc.decode(padded_features)[0]
  File "/home/bread98/.local/lib/python3.8/site-packages/reedsolo.py", line 940, in decode
    rmes, recc, errata_pos = rs_correct_msg(chunk, nsym, fcr=self.fcr, generator=self.generator, erase_pos=e_pos, only_erasures=only_erasures)
  File "/home/bread98/.local/lib/python3.8/site-packages/reedsolo.py", line 748, in rs_correct_msg
    err_loc = rs_find_error_locator(fsynd, nsym, erase_count=len(erase_pos))
  File "/home/bread98/.local/lib/python3.8/site-packages/reedsolo.py", line 659, in rs_find_error_locator
    raise ReedSolomonError("Too many errors to correct")
reedsolo.ReedSolomonError: Too many errors to correct

Wrong user!
-------------------------------------------------------------------------------------------------
Traceback (most recent call last):
  File "/mnt/c/BioMessages/reed_solomon/authentication.py", line 60, in authentication
    decoded_features = rsc.decode(padded_features)[0]
  File "/home/bread98/.local/lib/python3.8/site-packages/reedsolo.py", line 940, in decode
    rmes, recc, errata_pos = rs_correct_msg(chunk, nsym, fcr=self.fcr, generator=self.generator, erase_pos=e_pos, only_erasures=only_erasures)
  File "/home/bread98/.local/lib/python3.8/site-packages/reedsolo.py", line 748, in rs_correct_msg
    err_loc = rs_find_error_locator(fsynd, nsym, erase_count=len(erase_pos))
  File "/home/bread98/.local/lib/python3.8/site-packages/reedsolo.py", line 659, in rs_find_error_locator
    raise ReedSolomonError("Too many errors to correct")
reedsolo.ReedSolomonError: Too many errors to correct

Wrong user!
-------------------------------------------------------------------------------------------------



Successfully authenticated!
9326298952822749208227384749063203847536472917780309767474411783404472179322126350184834753408154036869327693557731646993809395925898017568169484450305928
-------------------------------------------------------------------------------------------------
Successfully authenticated!
9326298952822749208227384749063203847536472917780309767474411783404472179322126350184834753408154036869327693557731646993809395925898017568169484450305928
-------------------------------------------------------------------------------------------------
Successfully authenticated!
9326298952822749208227384749063203847536472917780309767474411783404472179322126350184834753408154036869327693557731646993809395925898017568169484450305928
-------------------------------------------------------------------------------------------------
Traceback (most recent call last):
  File "/mnt/c/BioMessages/reed_solomon/authentication.py", line 60, in authentication
    decoded_features = rsc.decode(padded_features)[0]
  File "/home/bread98/.local/lib/python3.8/site-packages/reedsolo.py", line 940, in decode
    rmes, recc, errata_pos = rs_correct_msg(chunk, nsym, fcr=self.fcr, generator=self.generator, erase_pos=e_pos, only_erasures=only_erasures)
  File "/home/bread98/.local/lib/python3.8/site-packages/reedsolo.py", line 748, in rs_correct_msg
    err_loc = rs_find_error_locator(fsynd, nsym, erase_count=len(erase_pos))
  File "/home/bread98/.local/lib/python3.8/site-packages/reedsolo.py", line 659, in rs_find_error_locator
    raise ReedSolomonError("Too many errors to correct")
reedsolo.ReedSolomonError: Too many errors to correct

Wrong user!
-------------------------------------------------------------------------------------------------



Successfully authenticated!
7221337900447364612088006278187395881474328823171614592920392714341719717771499766397479676883197278847217502671597122453016294055882607694883839796591732
-------------------------------------------------------------------------------------------------
Traceback (most recent call last):
  File "/mnt/c/BioMessages/reed_solomon/authentication.py", line 60, in authentication
    decoded_features = rsc.decode(padded_features)[0]
  File "/home/bread98/.local/lib/python3.8/site-packages/reedsolo.py", line 940, in decode
    rmes, recc, errata_pos = rs_correct_msg(chunk, nsym, fcr=self.fcr, generator=self.generator, erase_pos=e_pos, only_erasures=only_erasures)
  File "/home/bread98/.local/lib/python3.8/site-packages/reedsolo.py", line 748, in rs_correct_msg
    err_loc = rs_find_error_locator(fsynd, nsym, erase_count=len(erase_pos))
  File "/home/bread98/.local/lib/python3.8/site-packages/reedsolo.py", line 659, in rs_find_error_locator
    raise ReedSolomonError("Too many errors to correct")
reedsolo.ReedSolomonError: Too many errors to correct

Wrong user!
-------------------------------------------------------------------------------------------------
Successfully authenticated!
7221337900447364612088006278187395881474328823171614592920392714341719717771499766397479676883197278847217502671597122453016294055882607694883839796591732
-------------------------------------------------------------------------------------------------
Traceback (most recent call last):
  File "/mnt/c/BioMessages/reed_solomon/authentication.py", line 60, in authentication
    decoded_features = rsc.decode(padded_features)[0]
  File "/home/bread98/.local/lib/python3.8/site-packages/reedsolo.py", line 940, in decode
    rmes, recc, errata_pos = rs_correct_msg(chunk, nsym, fcr=self.fcr, generator=self.generator, erase_pos=e_pos, only_erasures=only_erasures)
  File "/home/bread98/.local/lib/python3.8/site-packages/reedsolo.py", line 748, in rs_correct_msg
    err_loc = rs_find_error_locator(fsynd, nsym, erase_count=len(erase_pos))
  File "/home/bread98/.local/lib/python3.8/site-packages/reedsolo.py", line 659, in rs_find_error_locator
    raise ReedSolomonError("Too many errors to correct")
reedsolo.ReedSolomonError: Too many errors to correct

Wrong user!
-------------------------------------------------------------------------------------------------



Successfully authenticated!
251983543313287542080939541852059186671917352902793687688508844033709836650742882171842636748023808217474277484442246017147648718152848483815652635186148
-------------------------------------------------------------------------------------------------
Successfully authenticated!
251983543313287542080939541852059186671917352902793687688508844033709836650742882171842636748023808217474277484442246017147648718152848483815652635186148
-------------------------------------------------------------------------------------------------
Traceback (most recent call last):
  File "/mnt/c/BioMessages/reed_solomon/authentication.py", line 60, in authentication
    decoded_features = rsc.decode(padded_features)[0]
  File "/home/bread98/.local/lib/python3.8/site-packages/reedsolo.py", line 940, in decode
    rmes, recc, errata_pos = rs_correct_msg(chunk, nsym, fcr=self.fcr, generator=self.generator, erase_pos=e_pos, only_erasures=only_erasures)
  File "/home/bread98/.local/lib/python3.8/site-packages/reedsolo.py", line 748, in rs_correct_msg
    err_loc = rs_find_error_locator(fsynd, nsym, erase_count=len(erase_pos))
  File "/home/bread98/.local/lib/python3.8/site-packages/reedsolo.py", line 659, in rs_find_error_locator
    raise ReedSolomonError("Too many errors to correct")
reedsolo.ReedSolomonError: Too many errors to correct

Wrong user!
-------------------------------------------------------------------------------------------------
Successfully authenticated!
251983543313287542080939541852059186671917352902793687688508844033709836650742882171842636748023808217474277484442246017147648718152848483815652635186148
-------------------------------------------------------------------------------------------------



Successfully authenticated!
8138307558110836363464590538907762756539849245820196444479223046434466672583159205483834875751278747261258648514279954185987069976591566908449327491410509
-------------------------------------------------------------------------------------------------
Successfully authenticated!
8138307558110836363464590538907762756539849245820196444479223046434466672583159205483834875751278747261258648514279954185987069976591566908449327491410509
-------------------------------------------------------------------------------------------------
Successfully authenticated!
8138307558110836363464590538907762756539849245820196444479223046434466672583159205483834875751278747261258648514279954185987069976591566908449327491410509
-------------------------------------------------------------------------------------------------
Successfully authenticated!
8138307558110836363464590538907762756539849245820196444479223046434466672583159205483834875751278747261258648514279954185987069976591566908449327491410509
-------------------------------------------------------------------------------------------------



Successfully authenticated!
3849323530977598956003808614758008049318666066403414699927899078667565128576359081761404442283259081036979988917092081817558192123264068715053740383744802
-------------------------------------------------------------------------------------------------
Successfully authenticated!
3849323530977598956003808614758008049318666066403414699927899078667565128576359081761404442283259081036979988917092081817558192123264068715053740383744802
-------------------------------------------------------------------------------------------------
Traceback (most recent call last):
  File "/mnt/c/BioMessages/reed_solomon/authentication.py", line 60, in authentication
    decoded_features = rsc.decode(padded_features)[0]
  File "/home/bread98/.local/lib/python3.8/site-packages/reedsolo.py", line 940, in decode
    rmes, recc, errata_pos = rs_correct_msg(chunk, nsym, fcr=self.fcr, generator=self.generator, erase_pos=e_pos, only_erasures=only_erasures)
  File "/home/bread98/.local/lib/python3.8/site-packages/reedsolo.py", line 748, in rs_correct_msg
    err_loc = rs_find_error_locator(fsynd, nsym, erase_count=len(erase_pos))
  File "/home/bread98/.local/lib/python3.8/site-packages/reedsolo.py", line 659, in rs_find_error_locator
    raise ReedSolomonError("Too many errors to correct")
reedsolo.ReedSolomonError: Too many errors to correct

Wrong user!
-------------------------------------------------------------------------------------------------
Successfully authenticated!
3849323530977598956003808614758008049318666066403414699927899078667565128576359081761404442283259081036979988917092081817558192123264068715053740383744802
-------------------------------------------------------------------------------------------------



Successfully authenticated!
6741716465258352288017576923987196355461100695362366558223871028982543116041230175486993164017497513066103951568961631314548152749450990932954370155894306
-------------------------------------------------------------------------------------------------
Successfully authenticated!
6741716465258352288017576923987196355461100695362366558223871028982543116041230175486993164017497513066103951568961631314548152749450990932954370155894306
-------------------------------------------------------------------------------------------------
Successfully authenticated!
6741716465258352288017576923987196355461100695362366558223871028982543116041230175486993164017497513066103951568961631314548152749450990932954370155894306
-------------------------------------------------------------------------------------------------
Successfully authenticated!
6741716465258352288017576923987196355461100695362366558223871028982543116041230175486993164017497513066103951568961631314548152749450990932954370155894306
-------------------------------------------------------------------------------------------------



Successfully authenticated!
1353156794246149445608452860277793384453450758592175053482563718699085460952535707497832464361435481377574257614651727223511048708509470678476654879108585
-------------------------------------------------------------------------------------------------
Successfully authenticated!
1353156794246149445608452860277793384453450758592175053482563718699085460952535707497832464361435481377574257614651727223511048708509470678476654879108585
-------------------------------------------------------------------------------------------------
Traceback (most recent call last):
  File "/mnt/c/BioMessages/reed_solomon/authentication.py", line 60, in authentication
    decoded_features = rsc.decode(padded_features)[0]
  File "/home/bread98/.local/lib/python3.8/site-packages/reedsolo.py", line 940, in decode
    rmes, recc, errata_pos = rs_correct_msg(chunk, nsym, fcr=self.fcr, generator=self.generator, erase_pos=e_pos, only_erasures=only_erasures)
  File "/home/bread98/.local/lib/python3.8/site-packages/reedsolo.py", line 748, in rs_correct_msg
    err_loc = rs_find_error_locator(fsynd, nsym, erase_count=len(erase_pos))
  File "/home/bread98/.local/lib/python3.8/site-packages/reedsolo.py", line 659, in rs_find_error_locator
    raise ReedSolomonError("Too many errors to correct")
reedsolo.ReedSolomonError: Too many errors to correct

Wrong user!
-------------------------------------------------------------------------------------------------
Successfully authenticated!
1353156794246149445608452860277793384453450758592175053482563718699085460952535707497832464361435481377574257614651727223511048708509470678476654879108585
-------------------------------------------------------------------------------------------------



Successfully authenticated!
9749413721526656113623846790420817909576105433137694862076002124951635541839709963118728987250534732014674246365788073504974476512129103961516047679535815
-------------------------------------------------------------------------------------------------
Successfully authenticated!
9749413721526656113623846790420817909576105433137694862076002124951635541839709963118728987250534732014674246365788073504974476512129103961516047679535815
-------------------------------------------------------------------------------------------------
Successfully authenticated!
9749413721526656113623846790420817909576105433137694862076002124951635541839709963118728987250534732014674246365788073504974476512129103961516047679535815
-------------------------------------------------------------------------------------------------
Successfully authenticated!
9749413721526656113623846790420817909576105433137694862076002124951635541839709963118728987250534732014674246365788073504974476512129103961516047679535815
-------------------------------------------------------------------------------------------------



Successfully authenticated!
6968087316899090234438962005602034620630028438723400832309032623969601060243083166794569550066044486081327819715378328025020831730844114957523117437231674
-------------------------------------------------------------------------------------------------
Successfully authenticated!
6968087316899090234438962005602034620630028438723400832309032623969601060243083166794569550066044486081327819715378328025020831730844114957523117437231674
-------------------------------------------------------------------------------------------------
Traceback (most recent call last):
  File "/mnt/c/BioMessages/reed_solomon/authentication.py", line 60, in authentication
    decoded_features = rsc.decode(padded_features)[0]
  File "/home/bread98/.local/lib/python3.8/site-packages/reedsolo.py", line 940, in decode
    rmes, recc, errata_pos = rs_correct_msg(chunk, nsym, fcr=self.fcr, generator=self.generator, erase_pos=e_pos, only_erasures=only_erasures)
  File "/home/bread98/.local/lib/python3.8/site-packages/reedsolo.py", line 748, in rs_correct_msg
    err_loc = rs_find_error_locator(fsynd, nsym, erase_count=len(erase_pos))
  File "/home/bread98/.local/lib/python3.8/site-packages/reedsolo.py", line 659, in rs_find_error_locator
    raise ReedSolomonError("Too many errors to correct")
reedsolo.ReedSolomonError: Too many errors to correct

Wrong user!
-------------------------------------------------------------------------------------------------
Successfully authenticated!
6968087316899090234438962005602034620630028438723400832309032623969601060243083166794569550066044486081327819715378328025020831730844114957523117437231674
-------------------------------------------------------------------------------------------------



Successfully authenticated!
6040400574802970260528011486387490327895594336358602091999325194204574526952470503183800435546885870830044656377808434653714259672211357756739158335016115
-------------------------------------------------------------------------------------------------
Traceback (most recent call last):
  File "/mnt/c/BioMessages/reed_solomon/authentication.py", line 60, in authentication
    decoded_features = rsc.decode(padded_features)[0]
  File "/home/bread98/.local/lib/python3.8/site-packages/reedsolo.py", line 940, in decode
    rmes, recc, errata_pos = rs_correct_msg(chunk, nsym, fcr=self.fcr, generator=self.generator, erase_pos=e_pos, only_erasures=only_erasures)
  File "/home/bread98/.local/lib/python3.8/site-packages/reedsolo.py", line 748, in rs_correct_msg
    err_loc = rs_find_error_locator(fsynd, nsym, erase_count=len(erase_pos))
  File "/home/bread98/.local/lib/python3.8/site-packages/reedsolo.py", line 659, in rs_find_error_locator
    raise ReedSolomonError("Too many errors to correct")
reedsolo.ReedSolomonError: Too many errors to correct

Wrong user!
-------------------------------------------------------------------------------------------------
Traceback (most recent call last):
  File "/mnt/c/BioMessages/reed_solomon/authentication.py", line 60, in authentication
    decoded_features = rsc.decode(padded_features)[0]
  File "/home/bread98/.local/lib/python3.8/site-packages/reedsolo.py", line 940, in decode
    rmes, recc, errata_pos = rs_correct_msg(chunk, nsym, fcr=self.fcr, generator=self.generator, erase_pos=e_pos, only_erasures=only_erasures)
  File "/home/bread98/.local/lib/python3.8/site-packages/reedsolo.py", line 748, in rs_correct_msg
    err_loc = rs_find_error_locator(fsynd, nsym, erase_count=len(erase_pos))
  File "/home/bread98/.local/lib/python3.8/site-packages/reedsolo.py", line 659, in rs_find_error_locator
    raise ReedSolomonError("Too many errors to correct")
reedsolo.ReedSolomonError: Too many errors to correct

Wrong user!
-------------------------------------------------------------------------------------------------
Successfully authenticated!
6040400574802970260528011486387490327895594336358602091999325194204574526952470503183800435546885870830044656377808434653714259672211357756739158335016115
-------------------------------------------------------------------------------------------------



Successfully authenticated!
11265637912534141749401816408216479575981008020801394174468896312201489826687877666013535136984620499140284963886443644548244988412892012887734121199231012
-------------------------------------------------------------------------------------------------
Traceback (most recent call last):
  File "/mnt/c/BioMessages/reed_solomon/authentication.py", line 60, in authentication
    decoded_features = rsc.decode(padded_features)[0]
  File "/home/bread98/.local/lib/python3.8/site-packages/reedsolo.py", line 940, in decode
    rmes, recc, errata_pos = rs_correct_msg(chunk, nsym, fcr=self.fcr, generator=self.generator, erase_pos=e_pos, only_erasures=only_erasures)
  File "/home/bread98/.local/lib/python3.8/site-packages/reedsolo.py", line 748, in rs_correct_msg
    err_loc = rs_find_error_locator(fsynd, nsym, erase_count=len(erase_pos))
  File "/home/bread98/.local/lib/python3.8/site-packages/reedsolo.py", line 659, in rs_find_error_locator
    raise ReedSolomonError("Too many errors to correct")
reedsolo.ReedSolomonError: Too many errors to correct

Wrong user!
-------------------------------------------------------------------------------------------------
Successfully authenticated!
11265637912534141749401816408216479575981008020801394174468896312201489826687877666013535136984620499140284963886443644548244988412892012887734121199231012
-------------------------------------------------------------------------------------------------
Successfully authenticated!
11265637912534141749401816408216479575981008020801394174468896312201489826687877666013535136984620499140284963886443644548244988412892012887734121199231012
-------------------------------------------------------------------------------------------------



Successfully authenticated!
3186266954642759198073182964260021977781725481998993360312319639412372171352518592100938991877643262846683044075247650071436572011563544650191266075787640
-------------------------------------------------------------------------------------------------
Traceback (most recent call last):
  File "/mnt/c/BioMessages/reed_solomon/authentication.py", line 60, in authentication
    decoded_features = rsc.decode(padded_features)[0]
  File "/home/bread98/.local/lib/python3.8/site-packages/reedsolo.py", line 940, in decode
    rmes, recc, errata_pos = rs_correct_msg(chunk, nsym, fcr=self.fcr, generator=self.generator, erase_pos=e_pos, only_erasures=only_erasures)
  File "/home/bread98/.local/lib/python3.8/site-packages/reedsolo.py", line 748, in rs_correct_msg
    err_loc = rs_find_error_locator(fsynd, nsym, erase_count=len(erase_pos))
  File "/home/bread98/.local/lib/python3.8/site-packages/reedsolo.py", line 659, in rs_find_error_locator
    raise ReedSolomonError("Too many errors to correct")
reedsolo.ReedSolomonError: Too many errors to correct

Wrong user!
-------------------------------------------------------------------------------------------------
Traceback (most recent call last):
  File "/mnt/c/BioMessages/reed_solomon/authentication.py", line 60, in authentication
    decoded_features = rsc.decode(padded_features)[0]
  File "/home/bread98/.local/lib/python3.8/site-packages/reedsolo.py", line 940, in decode
    rmes, recc, errata_pos = rs_correct_msg(chunk, nsym, fcr=self.fcr, generator=self.generator, erase_pos=e_pos, only_erasures=only_erasures)
  File "/home/bread98/.local/lib/python3.8/site-packages/reedsolo.py", line 748, in rs_correct_msg
    err_loc = rs_find_error_locator(fsynd, nsym, erase_count=len(erase_pos))
  File "/home/bread98/.local/lib/python3.8/site-packages/reedsolo.py", line 659, in rs_find_error_locator
    raise ReedSolomonError("Too many errors to correct")
reedsolo.ReedSolomonError: Too many errors to correct

Wrong user!
-------------------------------------------------------------------------------------------------
Traceback (most recent call last):
  File "/mnt/c/BioMessages/reed_solomon/authentication.py", line 60, in authentication
    decoded_features = rsc.decode(padded_features)[0]
  File "/home/bread98/.local/lib/python3.8/site-packages/reedsolo.py", line 940, in decode
    rmes, recc, errata_pos = rs_correct_msg(chunk, nsym, fcr=self.fcr, generator=self.generator, erase_pos=e_pos, only_erasures=only_erasures)
  File "/home/bread98/.local/lib/python3.8/site-packages/reedsolo.py", line 748, in rs_correct_msg
    err_loc = rs_find_error_locator(fsynd, nsym, erase_count=len(erase_pos))
  File "/home/bread98/.local/lib/python3.8/site-packages/reedsolo.py", line 659, in rs_find_error_locator
    raise ReedSolomonError("Too many errors to correct")
reedsolo.ReedSolomonError: Too many errors to correct

Wrong user!
-------------------------------------------------------------------------------------------------



Successfully authenticated!
8098086818975683626286193176046611462517869753717472364597925677886518536268575865644461028507234266592494060092240099528022602963150570157676906817883428
-------------------------------------------------------------------------------------------------
Traceback (most recent call last):
  File "/mnt/c/BioMessages/reed_solomon/authentication.py", line 60, in authentication
    decoded_features = rsc.decode(padded_features)[0]
  File "/home/bread98/.local/lib/python3.8/site-packages/reedsolo.py", line 940, in decode
    rmes, recc, errata_pos = rs_correct_msg(chunk, nsym, fcr=self.fcr, generator=self.generator, erase_pos=e_pos, only_erasures=only_erasures)
  File "/home/bread98/.local/lib/python3.8/site-packages/reedsolo.py", line 748, in rs_correct_msg
    err_loc = rs_find_error_locator(fsynd, nsym, erase_count=len(erase_pos))
  File "/home/bread98/.local/lib/python3.8/site-packages/reedsolo.py", line 659, in rs_find_error_locator
    raise ReedSolomonError("Too many errors to correct")
reedsolo.ReedSolomonError: Too many errors to correct

Wrong user!
-------------------------------------------------------------------------------------------------
Successfully authenticated!
8098086818975683626286193176046611462517869753717472364597925677886518536268575865644461028507234266592494060092240099528022602963150570157676906817883428
-------------------------------------------------------------------------------------------------
Successfully authenticated!
8098086818975683626286193176046611462517869753717472364597925677886518536268575865644461028507234266592494060092240099528022602963150570157676906817883428
-------------------------------------------------------------------------------------------------



Successfully authenticated!
8510931599778924129321777743486896278181039484289051367002505248146838075294593533931228641214902980879024716212815474573230037646560040902381210349736925
-------------------------------------------------------------------------------------------------
Successfully authenticated!
8510931599778924129321777743486896278181039484289051367002505248146838075294593533931228641214902980879024716212815474573230037646560040902381210349736925
-------------------------------------------------------------------------------------------------
Traceback (most recent call last):
  File "/mnt/c/BioMessages/reed_solomon/authentication.py", line 60, in authentication
    decoded_features = rsc.decode(padded_features)[0]
  File "/home/bread98/.local/lib/python3.8/site-packages/reedsolo.py", line 940, in decode
    rmes, recc, errata_pos = rs_correct_msg(chunk, nsym, fcr=self.fcr, generator=self.generator, erase_pos=e_pos, only_erasures=only_erasures)
  File "/home/bread98/.local/lib/python3.8/site-packages/reedsolo.py", line 748, in rs_correct_msg
    err_loc = rs_find_error_locator(fsynd, nsym, erase_count=len(erase_pos))
  File "/home/bread98/.local/lib/python3.8/site-packages/reedsolo.py", line 659, in rs_find_error_locator
    raise ReedSolomonError("Too many errors to correct")
reedsolo.ReedSolomonError: Too many errors to correct

Wrong user!
-------------------------------------------------------------------------------------------------
Successfully authenticated!
8510931599778924129321777743486896278181039484289051367002505248146838075294593533931228641214902980879024716212815474573230037646560040902381210349736925
-------------------------------------------------------------------------------------------------



Successfully authenticated!
9542724788549469025826155615670486690560635891205069862783719840238732176086834956746520804513567766938599209971145820551684454174040285396708209937909127
-------------------------------------------------------------------------------------------------
Successfully authenticated!
9542724788549469025826155615670486690560635891205069862783719840238732176086834956746520804513567766938599209971145820551684454174040285396708209937909127
-------------------------------------------------------------------------------------------------
Traceback (most recent call last):
  File "/mnt/c/BioMessages/reed_solomon/authentication.py", line 60, in authentication
    decoded_features = rsc.decode(padded_features)[0]
  File "/home/bread98/.local/lib/python3.8/site-packages/reedsolo.py", line 940, in decode
    rmes, recc, errata_pos = rs_correct_msg(chunk, nsym, fcr=self.fcr, generator=self.generator, erase_pos=e_pos, only_erasures=only_erasures)
  File "/home/bread98/.local/lib/python3.8/site-packages/reedsolo.py", line 748, in rs_correct_msg
    err_loc = rs_find_error_locator(fsynd, nsym, erase_count=len(erase_pos))
  File "/home/bread98/.local/lib/python3.8/site-packages/reedsolo.py", line 659, in rs_find_error_locator
    raise ReedSolomonError("Too many errors to correct")
reedsolo.ReedSolomonError: Too many errors to correct

Wrong user!
-------------------------------------------------------------------------------------------------
Traceback (most recent call last):
  File "/mnt/c/BioMessages/reed_solomon/authentication.py", line 60, in authentication
    decoded_features = rsc.decode(padded_features)[0]
  File "/home/bread98/.local/lib/python3.8/site-packages/reedsolo.py", line 940, in decode
    rmes, recc, errata_pos = rs_correct_msg(chunk, nsym, fcr=self.fcr, generator=self.generator, erase_pos=e_pos, only_erasures=only_erasures)
  File "/home/bread98/.local/lib/python3.8/site-packages/reedsolo.py", line 748, in rs_correct_msg
    err_loc = rs_find_error_locator(fsynd, nsym, erase_count=len(erase_pos))
  File "/home/bread98/.local/lib/python3.8/site-packages/reedsolo.py", line 659, in rs_find_error_locator
    raise ReedSolomonError("Too many errors to correct")
reedsolo.ReedSolomonError: Too many errors to correct

Wrong user!
-------------------------------------------------------------------------------------------------



Successfully authenticated!
330805590707908721094068626111548937126735389937722553552584835301119627771084996354856482833269732406460975884272477288338635817060728004226570074528684
-------------------------------------------------------------------------------------------------
Successfully authenticated!
330805590707908721094068626111548937126735389937722553552584835301119627771084996354856482833269732406460975884272477288338635817060728004226570074528684
-------------------------------------------------------------------------------------------------
Traceback (most recent call last):
  File "/mnt/c/BioMessages/reed_solomon/authentication.py", line 60, in authentication
    decoded_features = rsc.decode(padded_features)[0]
  File "/home/bread98/.local/lib/python3.8/site-packages/reedsolo.py", line 940, in decode
    rmes, recc, errata_pos = rs_correct_msg(chunk, nsym, fcr=self.fcr, generator=self.generator, erase_pos=e_pos, only_erasures=only_erasures)
  File "/home/bread98/.local/lib/python3.8/site-packages/reedsolo.py", line 748, in rs_correct_msg
    err_loc = rs_find_error_locator(fsynd, nsym, erase_count=len(erase_pos))
  File "/home/bread98/.local/lib/python3.8/site-packages/reedsolo.py", line 659, in rs_find_error_locator
    raise ReedSolomonError("Too many errors to correct")
reedsolo.ReedSolomonError: Too many errors to correct

Wrong user!
-------------------------------------------------------------------------------------------------
Successfully authenticated!
330805590707908721094068626111548937126735389937722553552584835301119627771084996354856482833269732406460975884272477288338635817060728004226570074528684
-------------------------------------------------------------------------------------------------



Successfully authenticated!
13243618981239640701153397028510773907790235894351743011174994572001590922347547357224394788478613168271678823705678339888052833608930092135776294700615017
-------------------------------------------------------------------------------------------------
Successfully authenticated!
13243618981239640701153397028510773907790235894351743011174994572001590922347547357224394788478613168271678823705678339888052833608930092135776294700615017
-------------------------------------------------------------------------------------------------
Successfully authenticated!
13243618981239640701153397028510773907790235894351743011174994572001590922347547357224394788478613168271678823705678339888052833608930092135776294700615017
-------------------------------------------------------------------------------------------------
Successfully authenticated!
13243618981239640701153397028510773907790235894351743011174994572001590922347547357224394788478613168271678823705678339888052833608930092135776294700615017
-------------------------------------------------------------------------------------------------



Successfully authenticated!
9188605533918159998207691321966590916310973382723092144992373696199727124356523599201070458239507806842109305202059728726658706744202406397045250839483952
-------------------------------------------------------------------------------------------------
Successfully authenticated!
9188605533918159998207691321966590916310973382723092144992373696199727124356523599201070458239507806842109305202059728726658706744202406397045250839483952
-------------------------------------------------------------------------------------------------
Successfully authenticated!
9188605533918159998207691321966590916310973382723092144992373696199727124356523599201070458239507806842109305202059728726658706744202406397045250839483952
-------------------------------------------------------------------------------------------------
Successfully authenticated!
9188605533918159998207691321966590916310973382723092144992373696199727124356523599201070458239507806842109305202059728726658706744202406397045250839483952
-------------------------------------------------------------------------------------------------



Successfully authenticated!
798892392273562355014072580624697000212311619518374637542437909075110473301530988476766532255820405131563007874794623921430463036472825286180764179321358
-------------------------------------------------------------------------------------------------
Successfully authenticated!
798892392273562355014072580624697000212311619518374637542437909075110473301530988476766532255820405131563007874794623921430463036472825286180764179321358
-------------------------------------------------------------------------------------------------
Traceback (most recent call last):
  File "/mnt/c/BioMessages/reed_solomon/authentication.py", line 60, in authentication
    decoded_features = rsc.decode(padded_features)[0]
  File "/home/bread98/.local/lib/python3.8/site-packages/reedsolo.py", line 940, in decode
    rmes, recc, errata_pos = rs_correct_msg(chunk, nsym, fcr=self.fcr, generator=self.generator, erase_pos=e_pos, only_erasures=only_erasures)
  File "/home/bread98/.local/lib/python3.8/site-packages/reedsolo.py", line 748, in rs_correct_msg
    err_loc = rs_find_error_locator(fsynd, nsym, erase_count=len(erase_pos))
  File "/home/bread98/.local/lib/python3.8/site-packages/reedsolo.py", line 659, in rs_find_error_locator
    raise ReedSolomonError("Too many errors to correct")
reedsolo.ReedSolomonError: Too many errors to correct

Wrong user!
-------------------------------------------------------------------------------------------------
Successfully authenticated!
798892392273562355014072580624697000212311619518374637542437909075110473301530988476766532255820405131563007874794623921430463036472825286180764179321358
-------------------------------------------------------------------------------------------------



Successfully authenticated!
7741476077294506588960836349351225011184564859892508027398797607399805880151918718670855546008932028577859077803766512610400180815052503668660994676365066
-------------------------------------------------------------------------------------------------
Successfully authenticated!
7741476077294506588960836349351225011184564859892508027398797607399805880151918718670855546008932028577859077803766512610400180815052503668660994676365066
-------------------------------------------------------------------------------------------------
Successfully authenticated!
7741476077294506588960836349351225011184564859892508027398797607399805880151918718670855546008932028577859077803766512610400180815052503668660994676365066
-------------------------------------------------------------------------------------------------
Successfully authenticated!
7741476077294506588960836349351225011184564859892508027398797607399805880151918718670855546008932028577859077803766512610400180815052503668660994676365066
-------------------------------------------------------------------------------------------------



Successfully authenticated!
3939705075807327047553701767245132918342374352070178580716639321157476971399422758334975457619605698707219781514509457640103712632982952781384405131006918
-------------------------------------------------------------------------------------------------
Successfully authenticated!
3939705075807327047553701767245132918342374352070178580716639321157476971399422758334975457619605698707219781514509457640103712632982952781384405131006918
-------------------------------------------------------------------------------------------------
Successfully authenticated!
3939705075807327047553701767245132918342374352070178580716639321157476971399422758334975457619605698707219781514509457640103712632982952781384405131006918
-------------------------------------------------------------------------------------------------
Traceback (most recent call last):
  File "/mnt/c/BioMessages/reed_solomon/authentication.py", line 60, in authentication
    decoded_features = rsc.decode(padded_features)[0]
  File "/home/bread98/.local/lib/python3.8/site-packages/reedsolo.py", line 940, in decode
    rmes, recc, errata_pos = rs_correct_msg(chunk, nsym, fcr=self.fcr, generator=self.generator, erase_pos=e_pos, only_erasures=only_erasures)
  File "/home/bread98/.local/lib/python3.8/site-packages/reedsolo.py", line 748, in rs_correct_msg
    err_loc = rs_find_error_locator(fsynd, nsym, erase_count=len(erase_pos))
  File "/home/bread98/.local/lib/python3.8/site-packages/reedsolo.py", line 659, in rs_find_error_locator
    raise ReedSolomonError("Too many errors to correct")
reedsolo.ReedSolomonError: Too many errors to correct

Wrong user!
-------------------------------------------------------------------------------------------------



Successfully authenticated!
4243151493699776668467112706914112282933992350418140087660075253337803620808488823780465912883853902736143636788496854955005693419676100907265876407822644
-------------------------------------------------------------------------------------------------
Successfully authenticated!
4243151493699776668467112706914112282933992350418140087660075253337803620808488823780465912883853902736143636788496854955005693419676100907265876407822644
-------------------------------------------------------------------------------------------------
Traceback (most recent call last):
  File "/mnt/c/BioMessages/reed_solomon/authentication.py", line 60, in authentication
    decoded_features = rsc.decode(padded_features)[0]
  File "/home/bread98/.local/lib/python3.8/site-packages/reedsolo.py", line 940, in decode
    rmes, recc, errata_pos = rs_correct_msg(chunk, nsym, fcr=self.fcr, generator=self.generator, erase_pos=e_pos, only_erasures=only_erasures)
  File "/home/bread98/.local/lib/python3.8/site-packages/reedsolo.py", line 748, in rs_correct_msg
    err_loc = rs_find_error_locator(fsynd, nsym, erase_count=len(erase_pos))
  File "/home/bread98/.local/lib/python3.8/site-packages/reedsolo.py", line 659, in rs_find_error_locator
    raise ReedSolomonError("Too many errors to correct")
reedsolo.ReedSolomonError: Too many errors to correct

Wrong user!
-------------------------------------------------------------------------------------------------
Successfully authenticated!
4243151493699776668467112706914112282933992350418140087660075253337803620808488823780465912883853902736143636788496854955005693419676100907265876407822644
-------------------------------------------------------------------------------------------------



Successfully authenticated!
5750601034828046661161418579756319939538396197332119305483282449147696115240819753006433321340722663686196021910254641757579742868132030713754588757982024
-------------------------------------------------------------------------------------------------
Successfully authenticated!
5750601034828046661161418579756319939538396197332119305483282449147696115240819753006433321340722663686196021910254641757579742868132030713754588757982024
-------------------------------------------------------------------------------------------------
Traceback (most recent call last):
  File "/mnt/c/BioMessages/reed_solomon/authentication.py", line 60, in authentication
    decoded_features = rsc.decode(padded_features)[0]
  File "/home/bread98/.local/lib/python3.8/site-packages/reedsolo.py", line 940, in decode
    rmes, recc, errata_pos = rs_correct_msg(chunk, nsym, fcr=self.fcr, generator=self.generator, erase_pos=e_pos, only_erasures=only_erasures)
  File "/home/bread98/.local/lib/python3.8/site-packages/reedsolo.py", line 748, in rs_correct_msg
    err_loc = rs_find_error_locator(fsynd, nsym, erase_count=len(erase_pos))
  File "/home/bread98/.local/lib/python3.8/site-packages/reedsolo.py", line 659, in rs_find_error_locator
    raise ReedSolomonError("Too many errors to correct")
reedsolo.ReedSolomonError: Too many errors to correct

Wrong user!
-------------------------------------------------------------------------------------------------
Successfully authenticated!
5750601034828046661161418579756319939538396197332119305483282449147696115240819753006433321340722663686196021910254641757579742868132030713754588757982024
-------------------------------------------------------------------------------------------------



Successfully authenticated!
8658720630710087137186933122060275063132537671587322280420962066428608434466910625463009696936208402634862473278319598354983900021123846956740231223249396
-------------------------------------------------------------------------------------------------
Successfully authenticated!
8658720630710087137186933122060275063132537671587322280420962066428608434466910625463009696936208402634862473278319598354983900021123846956740231223249396
-------------------------------------------------------------------------------------------------
Successfully authenticated!
8658720630710087137186933122060275063132537671587322280420962066428608434466910625463009696936208402634862473278319598354983900021123846956740231223249396
-------------------------------------------------------------------------------------------------
Traceback (most recent call last):
  File "/mnt/c/BioMessages/reed_solomon/authentication.py", line 60, in authentication
    decoded_features = rsc.decode(padded_features)[0]
  File "/home/bread98/.local/lib/python3.8/site-packages/reedsolo.py", line 940, in decode
    rmes, recc, errata_pos = rs_correct_msg(chunk, nsym, fcr=self.fcr, generator=self.generator, erase_pos=e_pos, only_erasures=only_erasures)
  File "/home/bread98/.local/lib/python3.8/site-packages/reedsolo.py", line 748, in rs_correct_msg
    err_loc = rs_find_error_locator(fsynd, nsym, erase_count=len(erase_pos))
  File "/home/bread98/.local/lib/python3.8/site-packages/reedsolo.py", line 659, in rs_find_error_locator
    raise ReedSolomonError("Too many errors to correct")
reedsolo.ReedSolomonError: Too many errors to correct

Wrong user!
-------------------------------------------------------------------------------------------------



Successfully authenticated!
9373115761098251642138490240449817057778506148561434426410766400435239992282067132028690833647014833940257880044024258200130440157281505379410741675704235
-------------------------------------------------------------------------------------------------
Traceback (most recent call last):
  File "/mnt/c/BioMessages/reed_solomon/authentication.py", line 60, in authentication
    decoded_features = rsc.decode(padded_features)[0]
  File "/home/bread98/.local/lib/python3.8/site-packages/reedsolo.py", line 940, in decode
    rmes, recc, errata_pos = rs_correct_msg(chunk, nsym, fcr=self.fcr, generator=self.generator, erase_pos=e_pos, only_erasures=only_erasures)
  File "/home/bread98/.local/lib/python3.8/site-packages/reedsolo.py", line 748, in rs_correct_msg
    err_loc = rs_find_error_locator(fsynd, nsym, erase_count=len(erase_pos))
  File "/home/bread98/.local/lib/python3.8/site-packages/reedsolo.py", line 659, in rs_find_error_locator
    raise ReedSolomonError("Too many errors to correct")
reedsolo.ReedSolomonError: Too many errors to correct

Wrong user!
-------------------------------------------------------------------------------------------------
Traceback (most recent call last):
  File "/mnt/c/BioMessages/reed_solomon/authentication.py", line 60, in authentication
    decoded_features = rsc.decode(padded_features)[0]
  File "/home/bread98/.local/lib/python3.8/site-packages/reedsolo.py", line 940, in decode
    rmes, recc, errata_pos = rs_correct_msg(chunk, nsym, fcr=self.fcr, generator=self.generator, erase_pos=e_pos, only_erasures=only_erasures)
  File "/home/bread98/.local/lib/python3.8/site-packages/reedsolo.py", line 748, in rs_correct_msg
    err_loc = rs_find_error_locator(fsynd, nsym, erase_count=len(erase_pos))
  File "/home/bread98/.local/lib/python3.8/site-packages/reedsolo.py", line 659, in rs_find_error_locator
    raise ReedSolomonError("Too many errors to correct")
reedsolo.ReedSolomonError: Too many errors to correct

Wrong user!
-------------------------------------------------------------------------------------------------
Traceback (most recent call last):
  File "/mnt/c/BioMessages/reed_solomon/authentication.py", line 60, in authentication
    decoded_features = rsc.decode(padded_features)[0]
  File "/home/bread98/.local/lib/python3.8/site-packages/reedsolo.py", line 940, in decode
    rmes, recc, errata_pos = rs_correct_msg(chunk, nsym, fcr=self.fcr, generator=self.generator, erase_pos=e_pos, only_erasures=only_erasures)
  File "/home/bread98/.local/lib/python3.8/site-packages/reedsolo.py", line 748, in rs_correct_msg
    err_loc = rs_find_error_locator(fsynd, nsym, erase_count=len(erase_pos))
  File "/home/bread98/.local/lib/python3.8/site-packages/reedsolo.py", line 659, in rs_find_error_locator
    raise ReedSolomonError("Too many errors to correct")
reedsolo.ReedSolomonError: Too many errors to correct

Wrong user!
-------------------------------------------------------------------------------------------------



Successfully authenticated!
5813832011735312342783686210617167500734001130127854050593465163157347943545662998036330487137897656745417920441964517112502416366052343474525231305649077
-------------------------------------------------------------------------------------------------
Successfully authenticated!
5813832011735312342783686210617167500734001130127854050593465163157347943545662998036330487137897656745417920441964517112502416366052343474525231305649077
-------------------------------------------------------------------------------------------------
Successfully authenticated!
5813832011735312342783686210617167500734001130127854050593465163157347943545662998036330487137897656745417920441964517112502416366052343474525231305649077
-------------------------------------------------------------------------------------------------
Traceback (most recent call last):
  File "/mnt/c/BioMessages/reed_solomon/authentication.py", line 60, in authentication
    decoded_features = rsc.decode(padded_features)[0]
  File "/home/bread98/.local/lib/python3.8/site-packages/reedsolo.py", line 940, in decode
    rmes, recc, errata_pos = rs_correct_msg(chunk, nsym, fcr=self.fcr, generator=self.generator, erase_pos=e_pos, only_erasures=only_erasures)
  File "/home/bread98/.local/lib/python3.8/site-packages/reedsolo.py", line 748, in rs_correct_msg
    err_loc = rs_find_error_locator(fsynd, nsym, erase_count=len(erase_pos))
  File "/home/bread98/.local/lib/python3.8/site-packages/reedsolo.py", line 659, in rs_find_error_locator
    raise ReedSolomonError("Too many errors to correct")
reedsolo.ReedSolomonError: Too many errors to correct

Wrong user!
-------------------------------------------------------------------------------------------------



Successfully authenticated!
2915667674582239488370016140362967296758979938127002640767338573411532731616402023948105936176884086359866800764437199380877735616382543553328759803192715
-------------------------------------------------------------------------------------------------
Successfully authenticated!
2915667674582239488370016140362967296758979938127002640767338573411532731616402023948105936176884086359866800764437199380877735616382543553328759803192715
-------------------------------------------------------------------------------------------------
Successfully authenticated!
2915667674582239488370016140362967296758979938127002640767338573411532731616402023948105936176884086359866800764437199380877735616382543553328759803192715
-------------------------------------------------------------------------------------------------
Successfully authenticated!
2915667674582239488370016140362967296758979938127002640767338573411532731616402023948105936176884086359866800764437199380877735616382543553328759803192715
-------------------------------------------------------------------------------------------------



Successfully authenticated!
9723474669211311521204666782349051023723416097720461208835837608365235980372322885727525123536894570638491380100236958025443707413061969820872438742246509
-------------------------------------------------------------------------------------------------
Successfully authenticated!
9723474669211311521204666782349051023723416097720461208835837608365235980372322885727525123536894570638491380100236958025443707413061969820872438742246509
-------------------------------------------------------------------------------------------------
Successfully authenticated!
9723474669211311521204666782349051023723416097720461208835837608365235980372322885727525123536894570638491380100236958025443707413061969820872438742246509
-------------------------------------------------------------------------------------------------
Successfully authenticated!
9723474669211311521204666782349051023723416097720461208835837608365235980372322885727525123536894570638491380100236958025443707413061969820872438742246509
-------------------------------------------------------------------------------------------------



Successfully authenticated!
9145968502800189369832547856165463158365281281763567618368452102167713590626205223716509469464717198604594551303853520012689837741055093750271318445779166
-------------------------------------------------------------------------------------------------
Traceback (most recent call last):
  File "/mnt/c/BioMessages/reed_solomon/authentication.py", line 60, in authentication
    decoded_features = rsc.decode(padded_features)[0]
  File "/home/bread98/.local/lib/python3.8/site-packages/reedsolo.py", line 940, in decode
    rmes, recc, errata_pos = rs_correct_msg(chunk, nsym, fcr=self.fcr, generator=self.generator, erase_pos=e_pos, only_erasures=only_erasures)
  File "/home/bread98/.local/lib/python3.8/site-packages/reedsolo.py", line 748, in rs_correct_msg
    err_loc = rs_find_error_locator(fsynd, nsym, erase_count=len(erase_pos))
  File "/home/bread98/.local/lib/python3.8/site-packages/reedsolo.py", line 659, in rs_find_error_locator
    raise ReedSolomonError("Too many errors to correct")
reedsolo.ReedSolomonError: Too many errors to correct

Wrong user!
-------------------------------------------------------------------------------------------------
Traceback (most recent call last):
  File "/mnt/c/BioMessages/reed_solomon/authentication.py", line 60, in authentication
    decoded_features = rsc.decode(padded_features)[0]
  File "/home/bread98/.local/lib/python3.8/site-packages/reedsolo.py", line 940, in decode
    rmes, recc, errata_pos = rs_correct_msg(chunk, nsym, fcr=self.fcr, generator=self.generator, erase_pos=e_pos, only_erasures=only_erasures)
  File "/home/bread98/.local/lib/python3.8/site-packages/reedsolo.py", line 748, in rs_correct_msg
    err_loc = rs_find_error_locator(fsynd, nsym, erase_count=len(erase_pos))
  File "/home/bread98/.local/lib/python3.8/site-packages/reedsolo.py", line 659, in rs_find_error_locator
    raise ReedSolomonError("Too many errors to correct")
reedsolo.ReedSolomonError: Too many errors to correct

Wrong user!
-------------------------------------------------------------------------------------------------
Traceback (most recent call last):
  File "/mnt/c/BioMessages/reed_solomon/authentication.py", line 60, in authentication
    decoded_features = rsc.decode(padded_features)[0]
  File "/home/bread98/.local/lib/python3.8/site-packages/reedsolo.py", line 940, in decode
    rmes, recc, errata_pos = rs_correct_msg(chunk, nsym, fcr=self.fcr, generator=self.generator, erase_pos=e_pos, only_erasures=only_erasures)
  File "/home/bread98/.local/lib/python3.8/site-packages/reedsolo.py", line 748, in rs_correct_msg
    err_loc = rs_find_error_locator(fsynd, nsym, erase_count=len(erase_pos))
  File "/home/bread98/.local/lib/python3.8/site-packages/reedsolo.py", line 659, in rs_find_error_locator
    raise ReedSolomonError("Too many errors to correct")
reedsolo.ReedSolomonError: Too many errors to correct

Wrong user!
-------------------------------------------------------------------------------------------------



Successfully authenticated!
9421398158835777918983787195007641420659243463124995008675773586687808710440253269448269571621405626226225973918201911596831270571246765974204818312059351
-------------------------------------------------------------------------------------------------
Successfully authenticated!
9421398158835777918983787195007641420659243463124995008675773586687808710440253269448269571621405626226225973918201911596831270571246765974204818312059351
-------------------------------------------------------------------------------------------------
Traceback (most recent call last):
  File "/mnt/c/BioMessages/reed_solomon/authentication.py", line 60, in authentication
    decoded_features = rsc.decode(padded_features)[0]
  File "/home/bread98/.local/lib/python3.8/site-packages/reedsolo.py", line 940, in decode
    rmes, recc, errata_pos = rs_correct_msg(chunk, nsym, fcr=self.fcr, generator=self.generator, erase_pos=e_pos, only_erasures=only_erasures)
  File "/home/bread98/.local/lib/python3.8/site-packages/reedsolo.py", line 748, in rs_correct_msg
    err_loc = rs_find_error_locator(fsynd, nsym, erase_count=len(erase_pos))
  File "/home/bread98/.local/lib/python3.8/site-packages/reedsolo.py", line 659, in rs_find_error_locator
    raise ReedSolomonError("Too many errors to correct")
reedsolo.ReedSolomonError: Too many errors to correct

Wrong user!
-------------------------------------------------------------------------------------------------
Successfully authenticated!
9421398158835777918983787195007641420659243463124995008675773586687808710440253269448269571621405626226225973918201911596831270571246765974204818312059351
-------------------------------------------------------------------------------------------------



Successfully authenticated!
8232727710173385612374175344978264925185755416203746059358159901954362486836454993154023242714620700584481173847498550895217361426566959741972426497244743
-------------------------------------------------------------------------------------------------
Successfully authenticated!
8232727710173385612374175344978264925185755416203746059358159901954362486836454993154023242714620700584481173847498550895217361426566959741972426497244743
-------------------------------------------------------------------------------------------------
Traceback (most recent call last):
  File "/mnt/c/BioMessages/reed_solomon/authentication.py", line 60, in authentication
    decoded_features = rsc.decode(padded_features)[0]
  File "/home/bread98/.local/lib/python3.8/site-packages/reedsolo.py", line 940, in decode
    rmes, recc, errata_pos = rs_correct_msg(chunk, nsym, fcr=self.fcr, generator=self.generator, erase_pos=e_pos, only_erasures=only_erasures)
  File "/home/bread98/.local/lib/python3.8/site-packages/reedsolo.py", line 748, in rs_correct_msg
    err_loc = rs_find_error_locator(fsynd, nsym, erase_count=len(erase_pos))
  File "/home/bread98/.local/lib/python3.8/site-packages/reedsolo.py", line 659, in rs_find_error_locator
    raise ReedSolomonError("Too many errors to correct")
reedsolo.ReedSolomonError: Too many errors to correct

Wrong user!
-------------------------------------------------------------------------------------------------
Successfully authenticated!
8232727710173385612374175344978264925185755416203746059358159901954362486836454993154023242714620700584481173847498550895217361426566959741972426497244743
-------------------------------------------------------------------------------------------------



Successfully authenticated!
5649151567043063570587853205720218063842509188069212752942035219248247831217066539996453607799882909956708509043093646045101209969321163834350741500360086
-------------------------------------------------------------------------------------------------
Traceback (most recent call last):
  File "/mnt/c/BioMessages/reed_solomon/authentication.py", line 60, in authentication
    decoded_features = rsc.decode(padded_features)[0]
  File "/home/bread98/.local/lib/python3.8/site-packages/reedsolo.py", line 940, in decode
    rmes, recc, errata_pos = rs_correct_msg(chunk, nsym, fcr=self.fcr, generator=self.generator, erase_pos=e_pos, only_erasures=only_erasures)
  File "/home/bread98/.local/lib/python3.8/site-packages/reedsolo.py", line 748, in rs_correct_msg
    err_loc = rs_find_error_locator(fsynd, nsym, erase_count=len(erase_pos))
  File "/home/bread98/.local/lib/python3.8/site-packages/reedsolo.py", line 659, in rs_find_error_locator
    raise ReedSolomonError("Too many errors to correct")
reedsolo.ReedSolomonError: Too many errors to correct

Wrong user!
-------------------------------------------------------------------------------------------------
Successfully authenticated!
5649151567043063570587853205720218063842509188069212752942035219248247831217066539996453607799882909956708509043093646045101209969321163834350741500360086
-------------------------------------------------------------------------------------------------
Successfully authenticated!
5649151567043063570587853205720218063842509188069212752942035219248247831217066539996453607799882909956708509043093646045101209969321163834350741500360086
-------------------------------------------------------------------------------------------------



Successfully authenticated!
430739086573143782221140487474775703095228667312214919151803987651670848678531347050541801163707103099243004715818991762989807411845073250432004800940288
-------------------------------------------------------------------------------------------------
Successfully authenticated!
430739086573143782221140487474775703095228667312214919151803987651670848678531347050541801163707103099243004715818991762989807411845073250432004800940288
-------------------------------------------------------------------------------------------------
Successfully authenticated!
430739086573143782221140487474775703095228667312214919151803987651670848678531347050541801163707103099243004715818991762989807411845073250432004800940288
-------------------------------------------------------------------------------------------------
Successfully authenticated!
430739086573143782221140487474775703095228667312214919151803987651670848678531347050541801163707103099243004715818991762989807411845073250432004800940288
-------------------------------------------------------------------------------------------------



Successfully authenticated!
5888496927886330300286264653885863475843880287812597624898577377393577237829796636575118068712614464011829139853762028158119826446419414330099214025651583
-------------------------------------------------------------------------------------------------
Successfully authenticated!
5888496927886330300286264653885863475843880287812597624898577377393577237829796636575118068712614464011829139853762028158119826446419414330099214025651583
-------------------------------------------------------------------------------------------------
Successfully authenticated!
5888496927886330300286264653885863475843880287812597624898577377393577237829796636575118068712614464011829139853762028158119826446419414330099214025651583
-------------------------------------------------------------------------------------------------
Traceback (most recent call last):
  File "/mnt/c/BioMessages/reed_solomon/authentication.py", line 60, in authentication
    decoded_features = rsc.decode(padded_features)[0]
  File "/home/bread98/.local/lib/python3.8/site-packages/reedsolo.py", line 940, in decode
    rmes, recc, errata_pos = rs_correct_msg(chunk, nsym, fcr=self.fcr, generator=self.generator, erase_pos=e_pos, only_erasures=only_erasures)
  File "/home/bread98/.local/lib/python3.8/site-packages/reedsolo.py", line 748, in rs_correct_msg
    err_loc = rs_find_error_locator(fsynd, nsym, erase_count=len(erase_pos))
  File "/home/bread98/.local/lib/python3.8/site-packages/reedsolo.py", line 659, in rs_find_error_locator
    raise ReedSolomonError("Too many errors to correct")
reedsolo.ReedSolomonError: Too many errors to correct

Wrong user!
-------------------------------------------------------------------------------------------------



Successfully authenticated!
7177423952378135955989010510154371617100719447718638803259421645150966199295086960681324986072417958483126954077860029534588323786814911282786735326642504
-------------------------------------------------------------------------------------------------
Successfully authenticated!
7177423952378135955989010510154371617100719447718638803259421645150966199295086960681324986072417958483126954077860029534588323786814911282786735326642504
-------------------------------------------------------------------------------------------------
Successfully authenticated!
7177423952378135955989010510154371617100719447718638803259421645150966199295086960681324986072417958483126954077860029534588323786814911282786735326642504
-------------------------------------------------------------------------------------------------
Successfully authenticated!
7177423952378135955989010510154371617100719447718638803259421645150966199295086960681324986072417958483126954077860029534588323786814911282786735326642504
-------------------------------------------------------------------------------------------------



Successfully authenticated!
1671062999497904993687653777514544391788393184693814262980794641536497212268883762410356464071531818499286725476059566107349447731815418168430062273134006
-------------------------------------------------------------------------------------------------
Successfully authenticated!
1671062999497904993687653777514544391788393184693814262980794641536497212268883762410356464071531818499286725476059566107349447731815418168430062273134006
-------------------------------------------------------------------------------------------------
Successfully authenticated!
1671062999497904993687653777514544391788393184693814262980794641536497212268883762410356464071531818499286725476059566107349447731815418168430062273134006
-------------------------------------------------------------------------------------------------
Traceback (most recent call last):
  File "/mnt/c/BioMessages/reed_solomon/authentication.py", line 60, in authentication
    decoded_features = rsc.decode(padded_features)[0]
  File "/home/bread98/.local/lib/python3.8/site-packages/reedsolo.py", line 940, in decode
    rmes, recc, errata_pos = rs_correct_msg(chunk, nsym, fcr=self.fcr, generator=self.generator, erase_pos=e_pos, only_erasures=only_erasures)
  File "/home/bread98/.local/lib/python3.8/site-packages/reedsolo.py", line 748, in rs_correct_msg
    err_loc = rs_find_error_locator(fsynd, nsym, erase_count=len(erase_pos))
  File "/home/bread98/.local/lib/python3.8/site-packages/reedsolo.py", line 659, in rs_find_error_locator
    raise ReedSolomonError("Too many errors to correct")
reedsolo.ReedSolomonError: Too many errors to correct

Wrong user!
-------------------------------------------------------------------------------------------------



Successfully authenticated!
3606056658705254662907264883902676005620096172319522954688180764303504217069621423654344838058562621363528406346035977014413504507472437749294918579022374
-------------------------------------------------------------------------------------------------
Successfully authenticated!
3606056658705254662907264883902676005620096172319522954688180764303504217069621423654344838058562621363528406346035977014413504507472437749294918579022374
-------------------------------------------------------------------------------------------------
Traceback (most recent call last):
  File "/mnt/c/BioMessages/reed_solomon/authentication.py", line 60, in authentication
    decoded_features = rsc.decode(padded_features)[0]
  File "/home/bread98/.local/lib/python3.8/site-packages/reedsolo.py", line 940, in decode
    rmes, recc, errata_pos = rs_correct_msg(chunk, nsym, fcr=self.fcr, generator=self.generator, erase_pos=e_pos, only_erasures=only_erasures)
  File "/home/bread98/.local/lib/python3.8/site-packages/reedsolo.py", line 748, in rs_correct_msg
    err_loc = rs_find_error_locator(fsynd, nsym, erase_count=len(erase_pos))
  File "/home/bread98/.local/lib/python3.8/site-packages/reedsolo.py", line 659, in rs_find_error_locator
    raise ReedSolomonError("Too many errors to correct")
reedsolo.ReedSolomonError: Too many errors to correct

Wrong user!
-------------------------------------------------------------------------------------------------
Traceback (most recent call last):
  File "/mnt/c/BioMessages/reed_solomon/authentication.py", line 60, in authentication
    decoded_features = rsc.decode(padded_features)[0]
  File "/home/bread98/.local/lib/python3.8/site-packages/reedsolo.py", line 940, in decode
    rmes, recc, errata_pos = rs_correct_msg(chunk, nsym, fcr=self.fcr, generator=self.generator, erase_pos=e_pos, only_erasures=only_erasures)
  File "/home/bread98/.local/lib/python3.8/site-packages/reedsolo.py", line 748, in rs_correct_msg
    err_loc = rs_find_error_locator(fsynd, nsym, erase_count=len(erase_pos))
  File "/home/bread98/.local/lib/python3.8/site-packages/reedsolo.py", line 659, in rs_find_error_locator
    raise ReedSolomonError("Too many errors to correct")
reedsolo.ReedSolomonError: Too many errors to correct

Wrong user!
-------------------------------------------------------------------------------------------------



Successfully authenticated!
5410845052612093574946010273363655321352357283842999134214152426923411812513559351966270843700268482540938138817803691759436235345983301760780273664105507
-------------------------------------------------------------------------------------------------
Successfully authenticated!
5410845052612093574946010273363655321352357283842999134214152426923411812513559351966270843700268482540938138817803691759436235345983301760780273664105507
-------------------------------------------------------------------------------------------------
Successfully authenticated!
5410845052612093574946010273363655321352357283842999134214152426923411812513559351966270843700268482540938138817803691759436235345983301760780273664105507
-------------------------------------------------------------------------------------------------
Traceback (most recent call last):
  File "/mnt/c/BioMessages/reed_solomon/authentication.py", line 60, in authentication
    decoded_features = rsc.decode(padded_features)[0]
  File "/home/bread98/.local/lib/python3.8/site-packages/reedsolo.py", line 940, in decode
    rmes, recc, errata_pos = rs_correct_msg(chunk, nsym, fcr=self.fcr, generator=self.generator, erase_pos=e_pos, only_erasures=only_erasures)
  File "/home/bread98/.local/lib/python3.8/site-packages/reedsolo.py", line 748, in rs_correct_msg
    err_loc = rs_find_error_locator(fsynd, nsym, erase_count=len(erase_pos))
  File "/home/bread98/.local/lib/python3.8/site-packages/reedsolo.py", line 659, in rs_find_error_locator
    raise ReedSolomonError("Too many errors to correct")
reedsolo.ReedSolomonError: Too many errors to correct

Wrong user!
-------------------------------------------------------------------------------------------------



Successfully authenticated!
3551692189532732487690545659219793673752452875753688193848419135465708468786045082361127670769307308441192920996789326759881748613296552882154204704329686
-------------------------------------------------------------------------------------------------
Successfully authenticated!
3551692189532732487690545659219793673752452875753688193848419135465708468786045082361127670769307308441192920996789326759881748613296552882154204704329686
-------------------------------------------------------------------------------------------------
Successfully authenticated!
3551692189532732487690545659219793673752452875753688193848419135465708468786045082361127670769307308441192920996789326759881748613296552882154204704329686
-------------------------------------------------------------------------------------------------
Successfully authenticated!
3551692189532732487690545659219793673752452875753688193848419135465708468786045082361127670769307308441192920996789326759881748613296552882154204704329686
-------------------------------------------------------------------------------------------------



Successfully authenticated!
8986075877037372845811543572164716204952964668865368759314877665665506248415227669563361488731491315748896911446303576943984399350856620549354798377878360
-------------------------------------------------------------------------------------------------
Successfully authenticated!
8986075877037372845811543572164716204952964668865368759314877665665506248415227669563361488731491315748896911446303576943984399350856620549354798377878360
-------------------------------------------------------------------------------------------------
Successfully authenticated!
8986075877037372845811543572164716204952964668865368759314877665665506248415227669563361488731491315748896911446303576943984399350856620549354798377878360
-------------------------------------------------------------------------------------------------
Successfully authenticated!
8986075877037372845811543572164716204952964668865368759314877665665506248415227669563361488731491315748896911446303576943984399350856620549354798377878360
-------------------------------------------------------------------------------------------------



Successfully authenticated!
10249137887005420433061229560647431582175008536287577665867679465148733562557988348477659001400392248511406074656814617195135546027050698975749763549328800
-------------------------------------------------------------------------------------------------
Successfully authenticated!
10249137887005420433061229560647431582175008536287577665867679465148733562557988348477659001400392248511406074656814617195135546027050698975749763549328800
-------------------------------------------------------------------------------------------------
Successfully authenticated!
10249137887005420433061229560647431582175008536287577665867679465148733562557988348477659001400392248511406074656814617195135546027050698975749763549328800
-------------------------------------------------------------------------------------------------
Successfully authenticated!
10249137887005420433061229560647431582175008536287577665867679465148733562557988348477659001400392248511406074656814617195135546027050698975749763549328800
-------------------------------------------------------------------------------------------------



Successfully authenticated!
9805913784569214426659259799263385607896863460055920492520827229710896024658613601201147022347076130967055730238578467756877162668367233146192443342165177
-------------------------------------------------------------------------------------------------
Traceback (most recent call last):
  File "/mnt/c/BioMessages/reed_solomon/authentication.py", line 60, in authentication
    decoded_features = rsc.decode(padded_features)[0]
  File "/home/bread98/.local/lib/python3.8/site-packages/reedsolo.py", line 940, in decode
    rmes, recc, errata_pos = rs_correct_msg(chunk, nsym, fcr=self.fcr, generator=self.generator, erase_pos=e_pos, only_erasures=only_erasures)
  File "/home/bread98/.local/lib/python3.8/site-packages/reedsolo.py", line 748, in rs_correct_msg
    err_loc = rs_find_error_locator(fsynd, nsym, erase_count=len(erase_pos))
  File "/home/bread98/.local/lib/python3.8/site-packages/reedsolo.py", line 659, in rs_find_error_locator
    raise ReedSolomonError("Too many errors to correct")
reedsolo.ReedSolomonError: Too many errors to correct

Wrong user!
-------------------------------------------------------------------------------------------------
Traceback (most recent call last):
  File "/mnt/c/BioMessages/reed_solomon/authentication.py", line 60, in authentication
    decoded_features = rsc.decode(padded_features)[0]
  File "/home/bread98/.local/lib/python3.8/site-packages/reedsolo.py", line 940, in decode
    rmes, recc, errata_pos = rs_correct_msg(chunk, nsym, fcr=self.fcr, generator=self.generator, erase_pos=e_pos, only_erasures=only_erasures)
  File "/home/bread98/.local/lib/python3.8/site-packages/reedsolo.py", line 748, in rs_correct_msg
    err_loc = rs_find_error_locator(fsynd, nsym, erase_count=len(erase_pos))
  File "/home/bread98/.local/lib/python3.8/site-packages/reedsolo.py", line 659, in rs_find_error_locator
    raise ReedSolomonError("Too many errors to correct")
reedsolo.ReedSolomonError: Too many errors to correct

Wrong user!
-------------------------------------------------------------------------------------------------
Successfully authenticated!
9805913784569214426659259799263385607896863460055920492520827229710896024658613601201147022347076130967055730238578467756877162668367233146192443342165177
-------------------------------------------------------------------------------------------------



Successfully authenticated!
5036012597827332482284493715075233762615902884329221368939065597144652786666953290772463743510960817400038826639770589290612589994514064270809195013467812
-------------------------------------------------------------------------------------------------
Successfully authenticated!
5036012597827332482284493715075233762615902884329221368939065597144652786666953290772463743510960817400038826639770589290612589994514064270809195013467812
-------------------------------------------------------------------------------------------------
Successfully authenticated!
5036012597827332482284493715075233762615902884329221368939065597144652786666953290772463743510960817400038826639770589290612589994514064270809195013467812
-------------------------------------------------------------------------------------------------
Successfully authenticated!
5036012597827332482284493715075233762615902884329221368939065597144652786666953290772463743510960817400038826639770589290612589994514064270809195013467812
-------------------------------------------------------------------------------------------------



The FRR is: 0.26157407407407407
